18:52:55 | INFO | aiogram.dispatcher | Start polling
18:52:55 | INFO | aiogram.dispatcher | Run polling for bot @Rich_boostBot id=7189291350 - 'Rich boost'
18:54:02 | INFO | aiogram.event | Update id=424477394 is handled. Duration 469 ms by bot id=7189291350
18:57:05 | INFO | aiogram.dispatcher | Polling stopped
18:57:05 | INFO | aiogram.dispatcher | Polling stopped for bot @Rich_boostBot id=7189291350 - 'Rich boost'
18:57:10 | INFO | aiogram.dispatcher | Start polling
18:57:10 | INFO | aiogram.dispatcher | Run polling for bot @Rich_boostBot id=7189291350 - 'Rich boost'
18:57:13 | INFO | app.handlers.common | @soquoru (id=1189473577) –∏—Å–ø–æ–ª—å–∑–æ–≤–∞–ª /start
18:57:14 | INFO | aiogram.event | Update id=424477395 is handled. Duration 437 ms by bot id=7189291350
18:57:16 | INFO | app.handlers.common | @soquoru –≤—ã–±—Ä–∞–ª —Ä–µ–≥–∏–æ–Ω: üåê –ö—Ä–∏–ø—Ç–∞
18:57:16 | INFO | aiogram.event | Update id=424477396 is handled. Duration 202 ms by bot id=7189291350
18:59:12 | INFO | aiogram.dispatcher | Polling stopped
18:59:12 | INFO | aiogram.dispatcher | Polling stopped for bot @Rich_boostBot id=7189291350 - 'Rich boost'
18:59:15 | INFO | aiogram.dispatcher | Start polling
18:59:16 | INFO | aiogram.dispatcher | Run polling for bot @Rich_boostBot id=7189291350 - 'Rich boost'
18:59:19 | INFO | app.handlers.common | @soquoru (id=1189473577) –∏—Å–ø–æ–ª—å–∑–æ–≤–∞–ª /start
18:59:19 | INFO | aiogram.event | Update id=424477397 is handled. Duration 421 ms by bot id=7189291350
18:59:26 | INFO | app.handlers.common | @soquoru –≤—ã–±—Ä–∞–ª —Ä–µ–≥–∏–æ–Ω: üåê –ö—Ä–∏–ø—Ç–∞
18:59:26 | INFO | aiogram.event | Update id=424477398 is handled. Duration 140 ms by bot id=7189291350
18:59:30 | INFO | aiogram.dispatcher | Polling stopped
18:59:30 | INFO | aiogram.dispatcher | Polling stopped for bot @Rich_boostBot id=7189291350 - 'Rich boost'
19:00:10 | INFO | aiogram.dispatcher | Start polling
19:00:10 | INFO | aiogram.dispatcher | Run polling for bot @Rich_boostBot id=7189291350 - 'Rich boost'
19:00:12 | INFO | aiogram.dispatcher | Polling stopped
19:00:12 | INFO | aiogram.dispatcher | Polling stopped for bot @Rich_boostBot id=7189291350 - 'Rich boost'
19:13:03 | INFO | aiogram.dispatcher | Start polling
19:13:04 | INFO | aiogram.dispatcher | Run polling for bot @Rich_boostBot id=7189291350 - 'Rich boost'
19:35:05 | INFO | aiogram.dispatcher | Start polling
19:35:05 | INFO | aiogram.dispatcher | Run polling for bot @Rich_boostBot id=7189291350 - 'Rich boost'
19:35:11 | INFO | aiogram.event | Update id=424477399 is not handled. Duration 46 ms by bot id=7189291350
19:35:11 | ERROR | aiogram.event | Cause exception while process update id=424477399 by bot id=7189291350
OperationalError: (sqlite3.OperationalError) no such table: users
[SQL: SELECT users.id, users.tg_id, users.username, users.region, users.role, users.created_at 
FROM users 
WHERE users.tg_id = ?]
[parameters: (1189473577,)]
(Background on this error at: https://sqlalche.me/e/20/e3q8)
Traceback (most recent call last):
  File "C:\Users\DeLL\Desktop\boost bot project 8k\rich_boost\venv\Lib\site-packages\sqlalchemy\engine\base.py", line 1969, in _exec_single_context
    self.dialect.do_execute(
  File "C:\Users\DeLL\Desktop\boost bot project 8k\rich_boost\venv\Lib\site-packages\sqlalchemy\engine\default.py", line 922, in do_execute
    cursor.execute(statement, parameters)
  File "C:\Users\DeLL\Desktop\boost bot project 8k\rich_boost\venv\Lib\site-packages\sqlalchemy\dialects\sqlite\aiosqlite.py", line 146, in execute
    self._adapt_connection._handle_exception(error)
  File "C:\Users\DeLL\Desktop\boost bot project 8k\rich_boost\venv\Lib\site-packages\sqlalchemy\dialects\sqlite\aiosqlite.py", line 298, in _handle_exception
    raise error
  File "C:\Users\DeLL\Desktop\boost bot project 8k\rich_boost\venv\Lib\site-packages\sqlalchemy\dialects\sqlite\aiosqlite.py", line 128, in execute
    self.await_(_cursor.execute(operation, parameters))
  File "C:\Users\DeLL\Desktop\boost bot project 8k\rich_boost\venv\Lib\site-packages\sqlalchemy\util\_concurrency_py3k.py", line 130, in await_only
    return current.driver.switch(awaitable)  # type: ignore[no-any-return]
           ^^^^^^^^^^^^^^^^^^^^^^^^^^^^^^^^
  File "C:\Users\DeLL\Desktop\boost bot project 8k\rich_boost\venv\Lib\site-packages\sqlalchemy\util\_concurrency_py3k.py", line 195, in greenlet_spawn
    value = await result
            ^^^^^^^^^^^^
  File "C:\Users\DeLL\Desktop\boost bot project 8k\rich_boost\venv\Lib\site-packages\aiosqlite\cursor.py", line 40, in execute
    await self._execute(self._cursor.execute, sql, parameters)
  File "C:\Users\DeLL\Desktop\boost bot project 8k\rich_boost\venv\Lib\site-packages\aiosqlite\cursor.py", line 32, in _execute
    return await self._conn._execute(fn, *args, **kwargs)
           ^^^^^^^^^^^^^^^^^^^^^^^^^^^^^^^^^^^^^^^^^^^^^^
  File "C:\Users\DeLL\Desktop\boost bot project 8k\rich_boost\venv\Lib\site-packages\aiosqlite\core.py", line 122, in _execute
    return await future
           ^^^^^^^^^^^^
  File "C:\Users\DeLL\Desktop\boost bot project 8k\rich_boost\venv\Lib\site-packages\aiosqlite\core.py", line 105, in run
    result = function()
             ^^^^^^^^^^
sqlite3.OperationalError: no such table: users

The above exception was the direct cause of the following exception:

Traceback (most recent call last):
  File "C:\Users\DeLL\Desktop\boost bot project 8k\rich_boost\venv\Lib\site-packages\aiogram\dispatcher\dispatcher.py", line 309, in _process_update
    response = await self.feed_update(bot, update, **kwargs)
               ^^^^^^^^^^^^^^^^^^^^^^^^^^^^^^^^^^^^^^^^^^^^^
  File "C:\Users\DeLL\Desktop\boost bot project 8k\rich_boost\venv\Lib\site-packages\aiogram\dispatcher\dispatcher.py", line 158, in feed_update
    response = await self.update.wrap_outer_middleware(
               ^^^^^^^^^^^^^^^^^^^^^^^^^^^^^^^^^^^^^^^^
  File "C:\Users\DeLL\Desktop\boost bot project 8k\rich_boost\venv\Lib\site-packages\aiogram\dispatcher\middlewares\error.py", line 25, in __call__
    return await handler(event, data)
           ^^^^^^^^^^^^^^^^^^^^^^^^^^
  File "C:\Users\DeLL\Desktop\boost bot project 8k\rich_boost\venv\Lib\site-packages\aiogram\dispatcher\middlewares\user_context.py", line 27, in __call__
    return await handler(event, data)
           ^^^^^^^^^^^^^^^^^^^^^^^^^^
  File "C:\Users\DeLL\Desktop\boost bot project 8k\rich_boost\venv\Lib\site-packages\aiogram\fsm\middleware.py", line 41, in __call__
    return await handler(event, data)
           ^^^^^^^^^^^^^^^^^^^^^^^^^^
  File "C:\Users\DeLL\Desktop\boost bot project 8k\rich_boost\venv\Lib\site-packages\aiogram\dispatcher\event\telegram.py", line 121, in trigger
    return await wrapped_inner(event, kwargs)
           ^^^^^^^^^^^^^^^^^^^^^^^^^^^^^^^^^^
  File "C:\Users\DeLL\Desktop\boost bot project 8k\rich_boost\venv\Lib\site-packages\aiogram\dispatcher\event\handler.py", line 43, in call
    return await wrapped()
           ^^^^^^^^^^^^^^^
  File "C:\Users\DeLL\Desktop\boost bot project 8k\rich_boost\venv\Lib\site-packages\aiogram\dispatcher\dispatcher.py", line 276, in _listen_update
    return await self.propagate_event(update_type=update_type, event=event, **kwargs)
           ^^^^^^^^^^^^^^^^^^^^^^^^^^^^^^^^^^^^^^^^^^^^^^^^^^^^^^^^^^^^^^^^^^^^^^^^^^
  File "C:\Users\DeLL\Desktop\boost bot project 8k\rich_boost\venv\Lib\site-packages\aiogram\dispatcher\router.py", line 128, in propagate_event
    return await observer.wrap_outer_middleware(_wrapped, event=event, data=kwargs)
           ^^^^^^^^^^^^^^^^^^^^^^^^^^^^^^^^^^^^^^^^^^^^^^^^^^^^^^^^^^^^^^^^^^^^^^^^
  File "C:\Users\DeLL\Desktop\boost bot project 8k\rich_boost\venv\Lib\site-packages\aiogram\dispatcher\router.py", line 123, in _wrapped
    return await self._propagate_event(
           ^^^^^^^^^^^^^^^^^^^^^^^^^^^^
  File "C:\Users\DeLL\Desktop\boost bot project 8k\rich_boost\venv\Lib\site-packages\aiogram\dispatcher\router.py", line 156, in _propagate_event
    response = await router.propagate_event(update_type=update_type, event=event, **kwargs)
               ^^^^^^^^^^^^^^^^^^^^^^^^^^^^^^^^^^^^^^^^^^^^^^^^^^^^^^^^^^^^^^^^^^^^^^^^^^^^
  File "C:\Users\DeLL\Desktop\boost bot project 8k\rich_boost\venv\Lib\site-packages\aiogram\dispatcher\router.py", line 128, in propagate_event
    return await observer.wrap_outer_middleware(_wrapped, event=event, data=kwargs)
           ^^^^^^^^^^^^^^^^^^^^^^^^^^^^^^^^^^^^^^^^^^^^^^^^^^^^^^^^^^^^^^^^^^^^^^^^
  File "C:\Users\DeLL\Desktop\boost bot project 8k\rich_boost\venv\Lib\site-packages\aiogram\dispatcher\router.py", line 123, in _wrapped
    return await self._propagate_event(
           ^^^^^^^^^^^^^^^^^^^^^^^^^^^^
  File "C:\Users\DeLL\Desktop\boost bot project 8k\rich_boost\venv\Lib\site-packages\aiogram\dispatcher\router.py", line 148, in _propagate_event
    response = await observer.trigger(event, **kwargs)
               ^^^^^^^^^^^^^^^^^^^^^^^^^^^^^^^^^^^^^^^
  File "C:\Users\DeLL\Desktop\boost bot project 8k\rich_boost\venv\Lib\site-packages\aiogram\dispatcher\event\telegram.py", line 121, in trigger
    return await wrapped_inner(event, kwargs)
           ^^^^^^^^^^^^^^^^^^^^^^^^^^^^^^^^^^
  File "C:\Users\DeLL\Desktop\boost bot project 8k\rich_boost\venv\Lib\site-packages\aiogram\dispatcher\event\handler.py", line 43, in call
    return await wrapped()
           ^^^^^^^^^^^^^^^
  File "C:\Users\DeLL\Desktop\boost bot project 8k\rich_boost\app\handlers\common.py", line 24, in region_chosen
    await update_user_region(message.from_user.id, message.text)
  File "C:\Users\DeLL\Desktop\boost bot project 8k\rich_boost\app\database\crud.py", line 21, in update_user_region
    result = await session.execute(select(User).where(User.tg_id == tg_id))
             ^^^^^^^^^^^^^^^^^^^^^^^^^^^^^^^^^^^^^^^^^^^^^^^^^^^^^^^^^^^^^^
  File "C:\Users\DeLL\Desktop\boost bot project 8k\rich_boost\venv\Lib\site-packages\sqlalchemy\ext\asyncio\session.py", line 455, in execute
    result = await greenlet_spawn(
             ^^^^^^^^^^^^^^^^^^^^^
  File "C:\Users\DeLL\Desktop\boost bot project 8k\rich_boost\venv\Lib\site-packages\sqlalchemy\util\_concurrency_py3k.py", line 200, in greenlet_spawn
    result = context.throw(*sys.exc_info())
             ^^^^^^^^^^^^^^^^^^^^^^^^^^^^^^
  File "C:\Users\DeLL\Desktop\boost bot project 8k\rich_boost\venv\Lib\site-packages\sqlalchemy\orm\session.py", line 2308, in execute
    return self._execute_internal(
           ^^^^^^^^^^^^^^^^^^^^^^^
  File "C:\Users\DeLL\Desktop\boost bot project 8k\rich_boost\venv\Lib\site-packages\sqlalchemy\orm\session.py", line 2190, in _execute_internal
    result: Result[Any] = compile_state_cls.orm_execute_statement(
                          ^^^^^^^^^^^^^^^^^^^^^^^^^^^^^^^^^^^^^^^^
  File "C:\Users\DeLL\Desktop\boost bot project 8k\rich_boost\venv\Lib\site-packages\sqlalchemy\orm\context.py", line 293, in orm_execute_statement
    result = conn.execute(
             ^^^^^^^^^^^^^
  File "C:\Users\DeLL\Desktop\boost bot project 8k\rich_boost\venv\Lib\site-packages\sqlalchemy\engine\base.py", line 1416, in execute
    return meth(
           ^^^^^
  File "C:\Users\DeLL\Desktop\boost bot project 8k\rich_boost\venv\Lib\site-packages\sqlalchemy\sql\elements.py", line 517, in _execute_on_connection
    return connection._execute_clauseelement(
           ^^^^^^^^^^^^^^^^^^^^^^^^^^^^^^^^^^
  File "C:\Users\DeLL\Desktop\boost bot project 8k\rich_boost\venv\Lib\site-packages\sqlalchemy\engine\base.py", line 1639, in _execute_clauseelement
    ret = self._execute_context(
          ^^^^^^^^^^^^^^^^^^^^^^
  File "C:\Users\DeLL\Desktop\boost bot project 8k\rich_boost\venv\Lib\site-packages\sqlalchemy\engine\base.py", line 1848, in _execute_context
    return self._exec_single_context(
           ^^^^^^^^^^^^^^^^^^^^^^^^^^
  File "C:\Users\DeLL\Desktop\boost bot project 8k\rich_boost\venv\Lib\site-packages\sqlalchemy\engine\base.py", line 1988, in _exec_single_context
    self._handle_dbapi_exception(
  File "C:\Users\DeLL\Desktop\boost bot project 8k\rich_boost\venv\Lib\site-packages\sqlalchemy\engine\base.py", line 2344, in _handle_dbapi_exception
    raise sqlalchemy_exception.with_traceback(exc_info[2]) from e
  File "C:\Users\DeLL\Desktop\boost bot project 8k\rich_boost\venv\Lib\site-packages\sqlalchemy\engine\base.py", line 1969, in _exec_single_context
    self.dialect.do_execute(
  File "C:\Users\DeLL\Desktop\boost bot project 8k\rich_boost\venv\Lib\site-packages\sqlalchemy\engine\default.py", line 922, in do_execute
    cursor.execute(statement, parameters)
  File "C:\Users\DeLL\Desktop\boost bot project 8k\rich_boost\venv\Lib\site-packages\sqlalchemy\dialects\sqlite\aiosqlite.py", line 146, in execute
    self._adapt_connection._handle_exception(error)
  File "C:\Users\DeLL\Desktop\boost bot project 8k\rich_boost\venv\Lib\site-packages\sqlalchemy\dialects\sqlite\aiosqlite.py", line 298, in _handle_exception
    raise error
  File "C:\Users\DeLL\Desktop\boost bot project 8k\rich_boost\venv\Lib\site-packages\sqlalchemy\dialects\sqlite\aiosqlite.py", line 128, in execute
    self.await_(_cursor.execute(operation, parameters))
  File "C:\Users\DeLL\Desktop\boost bot project 8k\rich_boost\venv\Lib\site-packages\sqlalchemy\util\_concurrency_py3k.py", line 130, in await_only
    return current.driver.switch(awaitable)  # type: ignore[no-any-return]
           ^^^^^^^^^^^^^^^^^^^^^^^^^^^^^^^^
  File "C:\Users\DeLL\Desktop\boost bot project 8k\rich_boost\venv\Lib\site-packages\sqlalchemy\util\_concurrency_py3k.py", line 195, in greenlet_spawn
    value = await result
            ^^^^^^^^^^^^
  File "C:\Users\DeLL\Desktop\boost bot project 8k\rich_boost\venv\Lib\site-packages\aiosqlite\cursor.py", line 40, in execute
    await self._execute(self._cursor.execute, sql, parameters)
  File "C:\Users\DeLL\Desktop\boost bot project 8k\rich_boost\venv\Lib\site-packages\aiosqlite\cursor.py", line 32, in _execute
    return await self._conn._execute(fn, *args, **kwargs)
           ^^^^^^^^^^^^^^^^^^^^^^^^^^^^^^^^^^^^^^^^^^^^^^
  File "C:\Users\DeLL\Desktop\boost bot project 8k\rich_boost\venv\Lib\site-packages\aiosqlite\core.py", line 122, in _execute
    return await future
           ^^^^^^^^^^^^
  File "C:\Users\DeLL\Desktop\boost bot project 8k\rich_boost\venv\Lib\site-packages\aiosqlite\core.py", line 105, in run
    result = function()
             ^^^^^^^^^^
sqlalchemy.exc.OperationalError: (sqlite3.OperationalError) no such table: users
[SQL: SELECT users.id, users.tg_id, users.username, users.region, users.role, users.created_at 
FROM users 
WHERE users.tg_id = ?]
[parameters: (1189473577,)]
(Background on this error at: https://sqlalche.me/e/20/e3q8)
19:35:27 | INFO | aiogram.event | Update id=424477400 is not handled. Duration 0 ms by bot id=7189291350
19:35:27 | ERROR | aiogram.event | Cause exception while process update id=424477400 by bot id=7189291350
OperationalError: (sqlite3.OperationalError) no such table: users
[SQL: SELECT users.id, users.tg_id, users.username, users.region, users.role, users.created_at 
FROM users 
WHERE users.tg_id = ?]
[parameters: (1189473577,)]
(Background on this error at: https://sqlalche.me/e/20/e3q8)
Traceback (most recent call last):
  File "C:\Users\DeLL\Desktop\boost bot project 8k\rich_boost\venv\Lib\site-packages\sqlalchemy\engine\base.py", line 1969, in _exec_single_context
    self.dialect.do_execute(
  File "C:\Users\DeLL\Desktop\boost bot project 8k\rich_boost\venv\Lib\site-packages\sqlalchemy\engine\default.py", line 922, in do_execute
    cursor.execute(statement, parameters)
  File "C:\Users\DeLL\Desktop\boost bot project 8k\rich_boost\venv\Lib\site-packages\sqlalchemy\dialects\sqlite\aiosqlite.py", line 146, in execute
    self._adapt_connection._handle_exception(error)
  File "C:\Users\DeLL\Desktop\boost bot project 8k\rich_boost\venv\Lib\site-packages\sqlalchemy\dialects\sqlite\aiosqlite.py", line 298, in _handle_exception
    raise error
  File "C:\Users\DeLL\Desktop\boost bot project 8k\rich_boost\venv\Lib\site-packages\sqlalchemy\dialects\sqlite\aiosqlite.py", line 128, in execute
    self.await_(_cursor.execute(operation, parameters))
  File "C:\Users\DeLL\Desktop\boost bot project 8k\rich_boost\venv\Lib\site-packages\sqlalchemy\util\_concurrency_py3k.py", line 130, in await_only
    return current.driver.switch(awaitable)  # type: ignore[no-any-return]
           ^^^^^^^^^^^^^^^^^^^^^^^^^^^^^^^^
  File "C:\Users\DeLL\Desktop\boost bot project 8k\rich_boost\venv\Lib\site-packages\sqlalchemy\util\_concurrency_py3k.py", line 195, in greenlet_spawn
    value = await result
            ^^^^^^^^^^^^
  File "C:\Users\DeLL\Desktop\boost bot project 8k\rich_boost\venv\Lib\site-packages\aiosqlite\cursor.py", line 40, in execute
    await self._execute(self._cursor.execute, sql, parameters)
  File "C:\Users\DeLL\Desktop\boost bot project 8k\rich_boost\venv\Lib\site-packages\aiosqlite\cursor.py", line 32, in _execute
    return await self._conn._execute(fn, *args, **kwargs)
           ^^^^^^^^^^^^^^^^^^^^^^^^^^^^^^^^^^^^^^^^^^^^^^
  File "C:\Users\DeLL\Desktop\boost bot project 8k\rich_boost\venv\Lib\site-packages\aiosqlite\core.py", line 122, in _execute
    return await future
           ^^^^^^^^^^^^
  File "C:\Users\DeLL\Desktop\boost bot project 8k\rich_boost\venv\Lib\site-packages\aiosqlite\core.py", line 105, in run
    result = function()
             ^^^^^^^^^^
sqlite3.OperationalError: no such table: users

The above exception was the direct cause of the following exception:

Traceback (most recent call last):
  File "C:\Users\DeLL\Desktop\boost bot project 8k\rich_boost\venv\Lib\site-packages\aiogram\dispatcher\dispatcher.py", line 309, in _process_update
    response = await self.feed_update(bot, update, **kwargs)
               ^^^^^^^^^^^^^^^^^^^^^^^^^^^^^^^^^^^^^^^^^^^^^
  File "C:\Users\DeLL\Desktop\boost bot project 8k\rich_boost\venv\Lib\site-packages\aiogram\dispatcher\dispatcher.py", line 158, in feed_update
    response = await self.update.wrap_outer_middleware(
               ^^^^^^^^^^^^^^^^^^^^^^^^^^^^^^^^^^^^^^^^
  File "C:\Users\DeLL\Desktop\boost bot project 8k\rich_boost\venv\Lib\site-packages\aiogram\dispatcher\middlewares\error.py", line 25, in __call__
    return await handler(event, data)
           ^^^^^^^^^^^^^^^^^^^^^^^^^^
  File "C:\Users\DeLL\Desktop\boost bot project 8k\rich_boost\venv\Lib\site-packages\aiogram\dispatcher\middlewares\user_context.py", line 27, in __call__
    return await handler(event, data)
           ^^^^^^^^^^^^^^^^^^^^^^^^^^
  File "C:\Users\DeLL\Desktop\boost bot project 8k\rich_boost\venv\Lib\site-packages\aiogram\fsm\middleware.py", line 41, in __call__
    return await handler(event, data)
           ^^^^^^^^^^^^^^^^^^^^^^^^^^
  File "C:\Users\DeLL\Desktop\boost bot project 8k\rich_boost\venv\Lib\site-packages\aiogram\dispatcher\event\telegram.py", line 121, in trigger
    return await wrapped_inner(event, kwargs)
           ^^^^^^^^^^^^^^^^^^^^^^^^^^^^^^^^^^
  File "C:\Users\DeLL\Desktop\boost bot project 8k\rich_boost\venv\Lib\site-packages\aiogram\dispatcher\event\handler.py", line 43, in call
    return await wrapped()
           ^^^^^^^^^^^^^^^
  File "C:\Users\DeLL\Desktop\boost bot project 8k\rich_boost\venv\Lib\site-packages\aiogram\dispatcher\dispatcher.py", line 276, in _listen_update
    return await self.propagate_event(update_type=update_type, event=event, **kwargs)
           ^^^^^^^^^^^^^^^^^^^^^^^^^^^^^^^^^^^^^^^^^^^^^^^^^^^^^^^^^^^^^^^^^^^^^^^^^^
  File "C:\Users\DeLL\Desktop\boost bot project 8k\rich_boost\venv\Lib\site-packages\aiogram\dispatcher\router.py", line 128, in propagate_event
    return await observer.wrap_outer_middleware(_wrapped, event=event, data=kwargs)
           ^^^^^^^^^^^^^^^^^^^^^^^^^^^^^^^^^^^^^^^^^^^^^^^^^^^^^^^^^^^^^^^^^^^^^^^^
  File "C:\Users\DeLL\Desktop\boost bot project 8k\rich_boost\venv\Lib\site-packages\aiogram\dispatcher\router.py", line 123, in _wrapped
    return await self._propagate_event(
           ^^^^^^^^^^^^^^^^^^^^^^^^^^^^
  File "C:\Users\DeLL\Desktop\boost bot project 8k\rich_boost\venv\Lib\site-packages\aiogram\dispatcher\router.py", line 156, in _propagate_event
    response = await router.propagate_event(update_type=update_type, event=event, **kwargs)
               ^^^^^^^^^^^^^^^^^^^^^^^^^^^^^^^^^^^^^^^^^^^^^^^^^^^^^^^^^^^^^^^^^^^^^^^^^^^^
  File "C:\Users\DeLL\Desktop\boost bot project 8k\rich_boost\venv\Lib\site-packages\aiogram\dispatcher\router.py", line 128, in propagate_event
    return await observer.wrap_outer_middleware(_wrapped, event=event, data=kwargs)
           ^^^^^^^^^^^^^^^^^^^^^^^^^^^^^^^^^^^^^^^^^^^^^^^^^^^^^^^^^^^^^^^^^^^^^^^^
  File "C:\Users\DeLL\Desktop\boost bot project 8k\rich_boost\venv\Lib\site-packages\aiogram\dispatcher\router.py", line 123, in _wrapped
    return await self._propagate_event(
           ^^^^^^^^^^^^^^^^^^^^^^^^^^^^
  File "C:\Users\DeLL\Desktop\boost bot project 8k\rich_boost\venv\Lib\site-packages\aiogram\dispatcher\router.py", line 148, in _propagate_event
    response = await observer.trigger(event, **kwargs)
               ^^^^^^^^^^^^^^^^^^^^^^^^^^^^^^^^^^^^^^^
  File "C:\Users\DeLL\Desktop\boost bot project 8k\rich_boost\venv\Lib\site-packages\aiogram\dispatcher\event\telegram.py", line 121, in trigger
    return await wrapped_inner(event, kwargs)
           ^^^^^^^^^^^^^^^^^^^^^^^^^^^^^^^^^^
  File "C:\Users\DeLL\Desktop\boost bot project 8k\rich_boost\venv\Lib\site-packages\aiogram\dispatcher\event\handler.py", line 43, in call
    return await wrapped()
           ^^^^^^^^^^^^^^^
  File "C:\Users\DeLL\Desktop\boost bot project 8k\rich_boost\app\handlers\common.py", line 12, in cmd_start
    await add_user(
  File "C:\Users\DeLL\Desktop\boost bot project 8k\rich_boost\app\database\crud.py", line 12, in add_user
    result = await session.execute(select(User).where(User.tg_id == tg_id))
             ^^^^^^^^^^^^^^^^^^^^^^^^^^^^^^^^^^^^^^^^^^^^^^^^^^^^^^^^^^^^^^
  File "C:\Users\DeLL\Desktop\boost bot project 8k\rich_boost\venv\Lib\site-packages\sqlalchemy\ext\asyncio\session.py", line 455, in execute
    result = await greenlet_spawn(
             ^^^^^^^^^^^^^^^^^^^^^
  File "C:\Users\DeLL\Desktop\boost bot project 8k\rich_boost\venv\Lib\site-packages\sqlalchemy\util\_concurrency_py3k.py", line 200, in greenlet_spawn
    result = context.throw(*sys.exc_info())
             ^^^^^^^^^^^^^^^^^^^^^^^^^^^^^^
  File "C:\Users\DeLL\Desktop\boost bot project 8k\rich_boost\venv\Lib\site-packages\sqlalchemy\orm\session.py", line 2308, in execute
    return self._execute_internal(
           ^^^^^^^^^^^^^^^^^^^^^^^
  File "C:\Users\DeLL\Desktop\boost bot project 8k\rich_boost\venv\Lib\site-packages\sqlalchemy\orm\session.py", line 2190, in _execute_internal
    result: Result[Any] = compile_state_cls.orm_execute_statement(
                          ^^^^^^^^^^^^^^^^^^^^^^^^^^^^^^^^^^^^^^^^
  File "C:\Users\DeLL\Desktop\boost bot project 8k\rich_boost\venv\Lib\site-packages\sqlalchemy\orm\context.py", line 293, in orm_execute_statement
    result = conn.execute(
             ^^^^^^^^^^^^^
  File "C:\Users\DeLL\Desktop\boost bot project 8k\rich_boost\venv\Lib\site-packages\sqlalchemy\engine\base.py", line 1416, in execute
    return meth(
           ^^^^^
  File "C:\Users\DeLL\Desktop\boost bot project 8k\rich_boost\venv\Lib\site-packages\sqlalchemy\sql\elements.py", line 517, in _execute_on_connection
    return connection._execute_clauseelement(
           ^^^^^^^^^^^^^^^^^^^^^^^^^^^^^^^^^^
  File "C:\Users\DeLL\Desktop\boost bot project 8k\rich_boost\venv\Lib\site-packages\sqlalchemy\engine\base.py", line 1639, in _execute_clauseelement
    ret = self._execute_context(
          ^^^^^^^^^^^^^^^^^^^^^^
  File "C:\Users\DeLL\Desktop\boost bot project 8k\rich_boost\venv\Lib\site-packages\sqlalchemy\engine\base.py", line 1848, in _execute_context
    return self._exec_single_context(
           ^^^^^^^^^^^^^^^^^^^^^^^^^^
  File "C:\Users\DeLL\Desktop\boost bot project 8k\rich_boost\venv\Lib\site-packages\sqlalchemy\engine\base.py", line 1988, in _exec_single_context
    self._handle_dbapi_exception(
  File "C:\Users\DeLL\Desktop\boost bot project 8k\rich_boost\venv\Lib\site-packages\sqlalchemy\engine\base.py", line 2344, in _handle_dbapi_exception
    raise sqlalchemy_exception.with_traceback(exc_info[2]) from e
  File "C:\Users\DeLL\Desktop\boost bot project 8k\rich_boost\venv\Lib\site-packages\sqlalchemy\engine\base.py", line 1969, in _exec_single_context
    self.dialect.do_execute(
  File "C:\Users\DeLL\Desktop\boost bot project 8k\rich_boost\venv\Lib\site-packages\sqlalchemy\engine\default.py", line 922, in do_execute
    cursor.execute(statement, parameters)
  File "C:\Users\DeLL\Desktop\boost bot project 8k\rich_boost\venv\Lib\site-packages\sqlalchemy\dialects\sqlite\aiosqlite.py", line 146, in execute
    self._adapt_connection._handle_exception(error)
  File "C:\Users\DeLL\Desktop\boost bot project 8k\rich_boost\venv\Lib\site-packages\sqlalchemy\dialects\sqlite\aiosqlite.py", line 298, in _handle_exception
    raise error
  File "C:\Users\DeLL\Desktop\boost bot project 8k\rich_boost\venv\Lib\site-packages\sqlalchemy\dialects\sqlite\aiosqlite.py", line 128, in execute
    self.await_(_cursor.execute(operation, parameters))
  File "C:\Users\DeLL\Desktop\boost bot project 8k\rich_boost\venv\Lib\site-packages\sqlalchemy\util\_concurrency_py3k.py", line 130, in await_only
    return current.driver.switch(awaitable)  # type: ignore[no-any-return]
           ^^^^^^^^^^^^^^^^^^^^^^^^^^^^^^^^
  File "C:\Users\DeLL\Desktop\boost bot project 8k\rich_boost\venv\Lib\site-packages\sqlalchemy\util\_concurrency_py3k.py", line 195, in greenlet_spawn
    value = await result
            ^^^^^^^^^^^^
  File "C:\Users\DeLL\Desktop\boost bot project 8k\rich_boost\venv\Lib\site-packages\aiosqlite\cursor.py", line 40, in execute
    await self._execute(self._cursor.execute, sql, parameters)
  File "C:\Users\DeLL\Desktop\boost bot project 8k\rich_boost\venv\Lib\site-packages\aiosqlite\cursor.py", line 32, in _execute
    return await self._conn._execute(fn, *args, **kwargs)
           ^^^^^^^^^^^^^^^^^^^^^^^^^^^^^^^^^^^^^^^^^^^^^^
  File "C:\Users\DeLL\Desktop\boost bot project 8k\rich_boost\venv\Lib\site-packages\aiosqlite\core.py", line 122, in _execute
    return await future
           ^^^^^^^^^^^^
  File "C:\Users\DeLL\Desktop\boost bot project 8k\rich_boost\venv\Lib\site-packages\aiosqlite\core.py", line 105, in run
    result = function()
             ^^^^^^^^^^
sqlalchemy.exc.OperationalError: (sqlite3.OperationalError) no such table: users
[SQL: SELECT users.id, users.tg_id, users.username, users.region, users.role, users.created_at 
FROM users 
WHERE users.tg_id = ?]
[parameters: (1189473577,)]
(Background on this error at: https://sqlalche.me/e/20/e3q8)
19:35:30 | INFO | aiogram.dispatcher | Polling stopped
19:35:30 | INFO | aiogram.dispatcher | Polling stopped for bot @Rich_boostBot id=7189291350 - 'Rich boost'
19:35:33 | INFO | aiogram.dispatcher | Start polling
19:35:34 | INFO | aiogram.dispatcher | Run polling for bot @Rich_boostBot id=7189291350 - 'Rich boost'
19:35:36 | INFO | aiogram.event | Update id=424477401 is not handled. Duration 15 ms by bot id=7189291350
19:35:36 | ERROR | aiogram.event | Cause exception while process update id=424477401 by bot id=7189291350
OperationalError: (sqlite3.OperationalError) no such table: users
[SQL: SELECT users.id, users.tg_id, users.username, users.region, users.role, users.created_at 
FROM users 
WHERE users.tg_id = ?]
[parameters: (1189473577,)]
(Background on this error at: https://sqlalche.me/e/20/e3q8)
Traceback (most recent call last):
  File "C:\Users\DeLL\Desktop\boost bot project 8k\rich_boost\venv\Lib\site-packages\sqlalchemy\engine\base.py", line 1969, in _exec_single_context
    self.dialect.do_execute(
  File "C:\Users\DeLL\Desktop\boost bot project 8k\rich_boost\venv\Lib\site-packages\sqlalchemy\engine\default.py", line 922, in do_execute
    cursor.execute(statement, parameters)
  File "C:\Users\DeLL\Desktop\boost bot project 8k\rich_boost\venv\Lib\site-packages\sqlalchemy\dialects\sqlite\aiosqlite.py", line 146, in execute
    self._adapt_connection._handle_exception(error)
  File "C:\Users\DeLL\Desktop\boost bot project 8k\rich_boost\venv\Lib\site-packages\sqlalchemy\dialects\sqlite\aiosqlite.py", line 298, in _handle_exception
    raise error
  File "C:\Users\DeLL\Desktop\boost bot project 8k\rich_boost\venv\Lib\site-packages\sqlalchemy\dialects\sqlite\aiosqlite.py", line 128, in execute
    self.await_(_cursor.execute(operation, parameters))
  File "C:\Users\DeLL\Desktop\boost bot project 8k\rich_boost\venv\Lib\site-packages\sqlalchemy\util\_concurrency_py3k.py", line 130, in await_only
    return current.driver.switch(awaitable)  # type: ignore[no-any-return]
           ^^^^^^^^^^^^^^^^^^^^^^^^^^^^^^^^
  File "C:\Users\DeLL\Desktop\boost bot project 8k\rich_boost\venv\Lib\site-packages\sqlalchemy\util\_concurrency_py3k.py", line 195, in greenlet_spawn
    value = await result
            ^^^^^^^^^^^^
  File "C:\Users\DeLL\Desktop\boost bot project 8k\rich_boost\venv\Lib\site-packages\aiosqlite\cursor.py", line 40, in execute
    await self._execute(self._cursor.execute, sql, parameters)
  File "C:\Users\DeLL\Desktop\boost bot project 8k\rich_boost\venv\Lib\site-packages\aiosqlite\cursor.py", line 32, in _execute
    return await self._conn._execute(fn, *args, **kwargs)
           ^^^^^^^^^^^^^^^^^^^^^^^^^^^^^^^^^^^^^^^^^^^^^^
  File "C:\Users\DeLL\Desktop\boost bot project 8k\rich_boost\venv\Lib\site-packages\aiosqlite\core.py", line 122, in _execute
    return await future
           ^^^^^^^^^^^^
  File "C:\Users\DeLL\Desktop\boost bot project 8k\rich_boost\venv\Lib\site-packages\aiosqlite\core.py", line 105, in run
    result = function()
             ^^^^^^^^^^
sqlite3.OperationalError: no such table: users

The above exception was the direct cause of the following exception:

Traceback (most recent call last):
  File "C:\Users\DeLL\Desktop\boost bot project 8k\rich_boost\venv\Lib\site-packages\aiogram\dispatcher\dispatcher.py", line 309, in _process_update
    response = await self.feed_update(bot, update, **kwargs)
               ^^^^^^^^^^^^^^^^^^^^^^^^^^^^^^^^^^^^^^^^^^^^^
  File "C:\Users\DeLL\Desktop\boost bot project 8k\rich_boost\venv\Lib\site-packages\aiogram\dispatcher\dispatcher.py", line 158, in feed_update
    response = await self.update.wrap_outer_middleware(
               ^^^^^^^^^^^^^^^^^^^^^^^^^^^^^^^^^^^^^^^^
  File "C:\Users\DeLL\Desktop\boost bot project 8k\rich_boost\venv\Lib\site-packages\aiogram\dispatcher\middlewares\error.py", line 25, in __call__
    return await handler(event, data)
           ^^^^^^^^^^^^^^^^^^^^^^^^^^
  File "C:\Users\DeLL\Desktop\boost bot project 8k\rich_boost\venv\Lib\site-packages\aiogram\dispatcher\middlewares\user_context.py", line 27, in __call__
    return await handler(event, data)
           ^^^^^^^^^^^^^^^^^^^^^^^^^^
  File "C:\Users\DeLL\Desktop\boost bot project 8k\rich_boost\venv\Lib\site-packages\aiogram\fsm\middleware.py", line 41, in __call__
    return await handler(event, data)
           ^^^^^^^^^^^^^^^^^^^^^^^^^^
  File "C:\Users\DeLL\Desktop\boost bot project 8k\rich_boost\venv\Lib\site-packages\aiogram\dispatcher\event\telegram.py", line 121, in trigger
    return await wrapped_inner(event, kwargs)
           ^^^^^^^^^^^^^^^^^^^^^^^^^^^^^^^^^^
  File "C:\Users\DeLL\Desktop\boost bot project 8k\rich_boost\venv\Lib\site-packages\aiogram\dispatcher\event\handler.py", line 43, in call
    return await wrapped()
           ^^^^^^^^^^^^^^^
  File "C:\Users\DeLL\Desktop\boost bot project 8k\rich_boost\venv\Lib\site-packages\aiogram\dispatcher\dispatcher.py", line 276, in _listen_update
    return await self.propagate_event(update_type=update_type, event=event, **kwargs)
           ^^^^^^^^^^^^^^^^^^^^^^^^^^^^^^^^^^^^^^^^^^^^^^^^^^^^^^^^^^^^^^^^^^^^^^^^^^
  File "C:\Users\DeLL\Desktop\boost bot project 8k\rich_boost\venv\Lib\site-packages\aiogram\dispatcher\router.py", line 128, in propagate_event
    return await observer.wrap_outer_middleware(_wrapped, event=event, data=kwargs)
           ^^^^^^^^^^^^^^^^^^^^^^^^^^^^^^^^^^^^^^^^^^^^^^^^^^^^^^^^^^^^^^^^^^^^^^^^
  File "C:\Users\DeLL\Desktop\boost bot project 8k\rich_boost\venv\Lib\site-packages\aiogram\dispatcher\router.py", line 123, in _wrapped
    return await self._propagate_event(
           ^^^^^^^^^^^^^^^^^^^^^^^^^^^^
  File "C:\Users\DeLL\Desktop\boost bot project 8k\rich_boost\venv\Lib\site-packages\aiogram\dispatcher\router.py", line 156, in _propagate_event
    response = await router.propagate_event(update_type=update_type, event=event, **kwargs)
               ^^^^^^^^^^^^^^^^^^^^^^^^^^^^^^^^^^^^^^^^^^^^^^^^^^^^^^^^^^^^^^^^^^^^^^^^^^^^
  File "C:\Users\DeLL\Desktop\boost bot project 8k\rich_boost\venv\Lib\site-packages\aiogram\dispatcher\router.py", line 128, in propagate_event
    return await observer.wrap_outer_middleware(_wrapped, event=event, data=kwargs)
           ^^^^^^^^^^^^^^^^^^^^^^^^^^^^^^^^^^^^^^^^^^^^^^^^^^^^^^^^^^^^^^^^^^^^^^^^
  File "C:\Users\DeLL\Desktop\boost bot project 8k\rich_boost\venv\Lib\site-packages\aiogram\dispatcher\router.py", line 123, in _wrapped
    return await self._propagate_event(
           ^^^^^^^^^^^^^^^^^^^^^^^^^^^^
  File "C:\Users\DeLL\Desktop\boost bot project 8k\rich_boost\venv\Lib\site-packages\aiogram\dispatcher\router.py", line 148, in _propagate_event
    response = await observer.trigger(event, **kwargs)
               ^^^^^^^^^^^^^^^^^^^^^^^^^^^^^^^^^^^^^^^
  File "C:\Users\DeLL\Desktop\boost bot project 8k\rich_boost\venv\Lib\site-packages\aiogram\dispatcher\event\telegram.py", line 121, in trigger
    return await wrapped_inner(event, kwargs)
           ^^^^^^^^^^^^^^^^^^^^^^^^^^^^^^^^^^
  File "C:\Users\DeLL\Desktop\boost bot project 8k\rich_boost\venv\Lib\site-packages\aiogram\dispatcher\event\handler.py", line 43, in call
    return await wrapped()
           ^^^^^^^^^^^^^^^
  File "C:\Users\DeLL\Desktop\boost bot project 8k\rich_boost\app\handlers\common.py", line 12, in cmd_start
    await add_user(
  File "C:\Users\DeLL\Desktop\boost bot project 8k\rich_boost\app\database\crud.py", line 12, in add_user
    result = await session.execute(select(User).where(User.tg_id == tg_id))
             ^^^^^^^^^^^^^^^^^^^^^^^^^^^^^^^^^^^^^^^^^^^^^^^^^^^^^^^^^^^^^^
  File "C:\Users\DeLL\Desktop\boost bot project 8k\rich_boost\venv\Lib\site-packages\sqlalchemy\ext\asyncio\session.py", line 455, in execute
    result = await greenlet_spawn(
             ^^^^^^^^^^^^^^^^^^^^^
  File "C:\Users\DeLL\Desktop\boost bot project 8k\rich_boost\venv\Lib\site-packages\sqlalchemy\util\_concurrency_py3k.py", line 200, in greenlet_spawn
    result = context.throw(*sys.exc_info())
             ^^^^^^^^^^^^^^^^^^^^^^^^^^^^^^
  File "C:\Users\DeLL\Desktop\boost bot project 8k\rich_boost\venv\Lib\site-packages\sqlalchemy\orm\session.py", line 2308, in execute
    return self._execute_internal(
           ^^^^^^^^^^^^^^^^^^^^^^^
  File "C:\Users\DeLL\Desktop\boost bot project 8k\rich_boost\venv\Lib\site-packages\sqlalchemy\orm\session.py", line 2190, in _execute_internal
    result: Result[Any] = compile_state_cls.orm_execute_statement(
                          ^^^^^^^^^^^^^^^^^^^^^^^^^^^^^^^^^^^^^^^^
  File "C:\Users\DeLL\Desktop\boost bot project 8k\rich_boost\venv\Lib\site-packages\sqlalchemy\orm\context.py", line 293, in orm_execute_statement
    result = conn.execute(
             ^^^^^^^^^^^^^
  File "C:\Users\DeLL\Desktop\boost bot project 8k\rich_boost\venv\Lib\site-packages\sqlalchemy\engine\base.py", line 1416, in execute
    return meth(
           ^^^^^
  File "C:\Users\DeLL\Desktop\boost bot project 8k\rich_boost\venv\Lib\site-packages\sqlalchemy\sql\elements.py", line 517, in _execute_on_connection
    return connection._execute_clauseelement(
           ^^^^^^^^^^^^^^^^^^^^^^^^^^^^^^^^^^
  File "C:\Users\DeLL\Desktop\boost bot project 8k\rich_boost\venv\Lib\site-packages\sqlalchemy\engine\base.py", line 1639, in _execute_clauseelement
    ret = self._execute_context(
          ^^^^^^^^^^^^^^^^^^^^^^
  File "C:\Users\DeLL\Desktop\boost bot project 8k\rich_boost\venv\Lib\site-packages\sqlalchemy\engine\base.py", line 1848, in _execute_context
    return self._exec_single_context(
           ^^^^^^^^^^^^^^^^^^^^^^^^^^
  File "C:\Users\DeLL\Desktop\boost bot project 8k\rich_boost\venv\Lib\site-packages\sqlalchemy\engine\base.py", line 1988, in _exec_single_context
    self._handle_dbapi_exception(
  File "C:\Users\DeLL\Desktop\boost bot project 8k\rich_boost\venv\Lib\site-packages\sqlalchemy\engine\base.py", line 2344, in _handle_dbapi_exception
    raise sqlalchemy_exception.with_traceback(exc_info[2]) from e
  File "C:\Users\DeLL\Desktop\boost bot project 8k\rich_boost\venv\Lib\site-packages\sqlalchemy\engine\base.py", line 1969, in _exec_single_context
    self.dialect.do_execute(
  File "C:\Users\DeLL\Desktop\boost bot project 8k\rich_boost\venv\Lib\site-packages\sqlalchemy\engine\default.py", line 922, in do_execute
    cursor.execute(statement, parameters)
  File "C:\Users\DeLL\Desktop\boost bot project 8k\rich_boost\venv\Lib\site-packages\sqlalchemy\dialects\sqlite\aiosqlite.py", line 146, in execute
    self._adapt_connection._handle_exception(error)
  File "C:\Users\DeLL\Desktop\boost bot project 8k\rich_boost\venv\Lib\site-packages\sqlalchemy\dialects\sqlite\aiosqlite.py", line 298, in _handle_exception
    raise error
  File "C:\Users\DeLL\Desktop\boost bot project 8k\rich_boost\venv\Lib\site-packages\sqlalchemy\dialects\sqlite\aiosqlite.py", line 128, in execute
    self.await_(_cursor.execute(operation, parameters))
  File "C:\Users\DeLL\Desktop\boost bot project 8k\rich_boost\venv\Lib\site-packages\sqlalchemy\util\_concurrency_py3k.py", line 130, in await_only
    return current.driver.switch(awaitable)  # type: ignore[no-any-return]
           ^^^^^^^^^^^^^^^^^^^^^^^^^^^^^^^^
  File "C:\Users\DeLL\Desktop\boost bot project 8k\rich_boost\venv\Lib\site-packages\sqlalchemy\util\_concurrency_py3k.py", line 195, in greenlet_spawn
    value = await result
            ^^^^^^^^^^^^
  File "C:\Users\DeLL\Desktop\boost bot project 8k\rich_boost\venv\Lib\site-packages\aiosqlite\cursor.py", line 40, in execute
    await self._execute(self._cursor.execute, sql, parameters)
  File "C:\Users\DeLL\Desktop\boost bot project 8k\rich_boost\venv\Lib\site-packages\aiosqlite\cursor.py", line 32, in _execute
    return await self._conn._execute(fn, *args, **kwargs)
           ^^^^^^^^^^^^^^^^^^^^^^^^^^^^^^^^^^^^^^^^^^^^^^
  File "C:\Users\DeLL\Desktop\boost bot project 8k\rich_boost\venv\Lib\site-packages\aiosqlite\core.py", line 122, in _execute
    return await future
           ^^^^^^^^^^^^
  File "C:\Users\DeLL\Desktop\boost bot project 8k\rich_boost\venv\Lib\site-packages\aiosqlite\core.py", line 105, in run
    result = function()
             ^^^^^^^^^^
sqlalchemy.exc.OperationalError: (sqlite3.OperationalError) no such table: users
[SQL: SELECT users.id, users.tg_id, users.username, users.region, users.role, users.created_at 
FROM users 
WHERE users.tg_id = ?]
[parameters: (1189473577,)]
(Background on this error at: https://sqlalche.me/e/20/e3q8)
19:55:30 | INFO | aiogram.dispatcher | Start polling
19:55:31 | INFO | aiogram.dispatcher | Run polling for bot @Rich_boostBot id=7189291350 - 'Rich boost'
19:57:22 | INFO | aiogram.event | Update id=424477402 is not handled. Duration 16 ms by bot id=7189291350
19:57:22 | ERROR | aiogram.event | Cause exception while process update id=424477402 by bot id=7189291350
OperationalError: (sqlite3.OperationalError) no such table: users
[SQL: SELECT users.id, users.tg_id, users.username, users.region, users.role, users.created_at 
FROM users 
WHERE users.tg_id = ?]
[parameters: (1189473577,)]
(Background on this error at: https://sqlalche.me/e/20/e3q8)
Traceback (most recent call last):
  File "C:\Users\DeLL\Desktop\boost bot project 8k\rich_boost\venv\Lib\site-packages\sqlalchemy\engine\base.py", line 1969, in _exec_single_context
    self.dialect.do_execute(
  File "C:\Users\DeLL\Desktop\boost bot project 8k\rich_boost\venv\Lib\site-packages\sqlalchemy\engine\default.py", line 922, in do_execute
    cursor.execute(statement, parameters)
  File "C:\Users\DeLL\Desktop\boost bot project 8k\rich_boost\venv\Lib\site-packages\sqlalchemy\dialects\sqlite\aiosqlite.py", line 146, in execute
    self._adapt_connection._handle_exception(error)
  File "C:\Users\DeLL\Desktop\boost bot project 8k\rich_boost\venv\Lib\site-packages\sqlalchemy\dialects\sqlite\aiosqlite.py", line 298, in _handle_exception
    raise error
  File "C:\Users\DeLL\Desktop\boost bot project 8k\rich_boost\venv\Lib\site-packages\sqlalchemy\dialects\sqlite\aiosqlite.py", line 128, in execute
    self.await_(_cursor.execute(operation, parameters))
  File "C:\Users\DeLL\Desktop\boost bot project 8k\rich_boost\venv\Lib\site-packages\sqlalchemy\util\_concurrency_py3k.py", line 130, in await_only
    return current.driver.switch(awaitable)  # type: ignore[no-any-return]
           ^^^^^^^^^^^^^^^^^^^^^^^^^^^^^^^^
  File "C:\Users\DeLL\Desktop\boost bot project 8k\rich_boost\venv\Lib\site-packages\sqlalchemy\util\_concurrency_py3k.py", line 195, in greenlet_spawn
    value = await result
            ^^^^^^^^^^^^
  File "C:\Users\DeLL\Desktop\boost bot project 8k\rich_boost\venv\Lib\site-packages\aiosqlite\cursor.py", line 40, in execute
    await self._execute(self._cursor.execute, sql, parameters)
  File "C:\Users\DeLL\Desktop\boost bot project 8k\rich_boost\venv\Lib\site-packages\aiosqlite\cursor.py", line 32, in _execute
    return await self._conn._execute(fn, *args, **kwargs)
           ^^^^^^^^^^^^^^^^^^^^^^^^^^^^^^^^^^^^^^^^^^^^^^
  File "C:\Users\DeLL\Desktop\boost bot project 8k\rich_boost\venv\Lib\site-packages\aiosqlite\core.py", line 122, in _execute
    return await future
           ^^^^^^^^^^^^
  File "C:\Users\DeLL\Desktop\boost bot project 8k\rich_boost\venv\Lib\site-packages\aiosqlite\core.py", line 105, in run
    result = function()
             ^^^^^^^^^^
sqlite3.OperationalError: no such table: users

The above exception was the direct cause of the following exception:

Traceback (most recent call last):
  File "C:\Users\DeLL\Desktop\boost bot project 8k\rich_boost\venv\Lib\site-packages\aiogram\dispatcher\dispatcher.py", line 309, in _process_update
    response = await self.feed_update(bot, update, **kwargs)
               ^^^^^^^^^^^^^^^^^^^^^^^^^^^^^^^^^^^^^^^^^^^^^
  File "C:\Users\DeLL\Desktop\boost bot project 8k\rich_boost\venv\Lib\site-packages\aiogram\dispatcher\dispatcher.py", line 158, in feed_update
    response = await self.update.wrap_outer_middleware(
               ^^^^^^^^^^^^^^^^^^^^^^^^^^^^^^^^^^^^^^^^
  File "C:\Users\DeLL\Desktop\boost bot project 8k\rich_boost\venv\Lib\site-packages\aiogram\dispatcher\middlewares\error.py", line 25, in __call__
    return await handler(event, data)
           ^^^^^^^^^^^^^^^^^^^^^^^^^^
  File "C:\Users\DeLL\Desktop\boost bot project 8k\rich_boost\venv\Lib\site-packages\aiogram\dispatcher\middlewares\user_context.py", line 27, in __call__
    return await handler(event, data)
           ^^^^^^^^^^^^^^^^^^^^^^^^^^
  File "C:\Users\DeLL\Desktop\boost bot project 8k\rich_boost\venv\Lib\site-packages\aiogram\fsm\middleware.py", line 41, in __call__
    return await handler(event, data)
           ^^^^^^^^^^^^^^^^^^^^^^^^^^
  File "C:\Users\DeLL\Desktop\boost bot project 8k\rich_boost\venv\Lib\site-packages\aiogram\dispatcher\event\telegram.py", line 121, in trigger
    return await wrapped_inner(event, kwargs)
           ^^^^^^^^^^^^^^^^^^^^^^^^^^^^^^^^^^
  File "C:\Users\DeLL\Desktop\boost bot project 8k\rich_boost\venv\Lib\site-packages\aiogram\dispatcher\event\handler.py", line 43, in call
    return await wrapped()
           ^^^^^^^^^^^^^^^
  File "C:\Users\DeLL\Desktop\boost bot project 8k\rich_boost\venv\Lib\site-packages\aiogram\dispatcher\dispatcher.py", line 276, in _listen_update
    return await self.propagate_event(update_type=update_type, event=event, **kwargs)
           ^^^^^^^^^^^^^^^^^^^^^^^^^^^^^^^^^^^^^^^^^^^^^^^^^^^^^^^^^^^^^^^^^^^^^^^^^^
  File "C:\Users\DeLL\Desktop\boost bot project 8k\rich_boost\venv\Lib\site-packages\aiogram\dispatcher\router.py", line 128, in propagate_event
    return await observer.wrap_outer_middleware(_wrapped, event=event, data=kwargs)
           ^^^^^^^^^^^^^^^^^^^^^^^^^^^^^^^^^^^^^^^^^^^^^^^^^^^^^^^^^^^^^^^^^^^^^^^^
  File "C:\Users\DeLL\Desktop\boost bot project 8k\rich_boost\venv\Lib\site-packages\aiogram\dispatcher\router.py", line 123, in _wrapped
    return await self._propagate_event(
           ^^^^^^^^^^^^^^^^^^^^^^^^^^^^
  File "C:\Users\DeLL\Desktop\boost bot project 8k\rich_boost\venv\Lib\site-packages\aiogram\dispatcher\router.py", line 156, in _propagate_event
    response = await router.propagate_event(update_type=update_type, event=event, **kwargs)
               ^^^^^^^^^^^^^^^^^^^^^^^^^^^^^^^^^^^^^^^^^^^^^^^^^^^^^^^^^^^^^^^^^^^^^^^^^^^^
  File "C:\Users\DeLL\Desktop\boost bot project 8k\rich_boost\venv\Lib\site-packages\aiogram\dispatcher\router.py", line 128, in propagate_event
    return await observer.wrap_outer_middleware(_wrapped, event=event, data=kwargs)
           ^^^^^^^^^^^^^^^^^^^^^^^^^^^^^^^^^^^^^^^^^^^^^^^^^^^^^^^^^^^^^^^^^^^^^^^^
  File "C:\Users\DeLL\Desktop\boost bot project 8k\rich_boost\venv\Lib\site-packages\aiogram\dispatcher\router.py", line 123, in _wrapped
    return await self._propagate_event(
           ^^^^^^^^^^^^^^^^^^^^^^^^^^^^
  File "C:\Users\DeLL\Desktop\boost bot project 8k\rich_boost\venv\Lib\site-packages\aiogram\dispatcher\router.py", line 148, in _propagate_event
    response = await observer.trigger(event, **kwargs)
               ^^^^^^^^^^^^^^^^^^^^^^^^^^^^^^^^^^^^^^^
  File "C:\Users\DeLL\Desktop\boost bot project 8k\rich_boost\venv\Lib\site-packages\aiogram\dispatcher\event\telegram.py", line 121, in trigger
    return await wrapped_inner(event, kwargs)
           ^^^^^^^^^^^^^^^^^^^^^^^^^^^^^^^^^^
  File "C:\Users\DeLL\Desktop\boost bot project 8k\rich_boost\venv\Lib\site-packages\aiogram\dispatcher\event\handler.py", line 43, in call
    return await wrapped()
           ^^^^^^^^^^^^^^^
  File "C:\Users\DeLL\Desktop\boost bot project 8k\rich_boost\app\handlers\common.py", line 12, in cmd_start
    await add_user(
  File "C:\Users\DeLL\Desktop\boost bot project 8k\rich_boost\app\database\crud.py", line 12, in add_user
    result = await session.execute(select(User).where(User.tg_id == tg_id))
             ^^^^^^^^^^^^^^^^^^^^^^^^^^^^^^^^^^^^^^^^^^^^^^^^^^^^^^^^^^^^^^
  File "C:\Users\DeLL\Desktop\boost bot project 8k\rich_boost\venv\Lib\site-packages\sqlalchemy\ext\asyncio\session.py", line 455, in execute
    result = await greenlet_spawn(
             ^^^^^^^^^^^^^^^^^^^^^
  File "C:\Users\DeLL\Desktop\boost bot project 8k\rich_boost\venv\Lib\site-packages\sqlalchemy\util\_concurrency_py3k.py", line 200, in greenlet_spawn
    result = context.throw(*sys.exc_info())
             ^^^^^^^^^^^^^^^^^^^^^^^^^^^^^^
  File "C:\Users\DeLL\Desktop\boost bot project 8k\rich_boost\venv\Lib\site-packages\sqlalchemy\orm\session.py", line 2308, in execute
    return self._execute_internal(
           ^^^^^^^^^^^^^^^^^^^^^^^
  File "C:\Users\DeLL\Desktop\boost bot project 8k\rich_boost\venv\Lib\site-packages\sqlalchemy\orm\session.py", line 2190, in _execute_internal
    result: Result[Any] = compile_state_cls.orm_execute_statement(
                          ^^^^^^^^^^^^^^^^^^^^^^^^^^^^^^^^^^^^^^^^
  File "C:\Users\DeLL\Desktop\boost bot project 8k\rich_boost\venv\Lib\site-packages\sqlalchemy\orm\context.py", line 293, in orm_execute_statement
    result = conn.execute(
             ^^^^^^^^^^^^^
  File "C:\Users\DeLL\Desktop\boost bot project 8k\rich_boost\venv\Lib\site-packages\sqlalchemy\engine\base.py", line 1416, in execute
    return meth(
           ^^^^^
  File "C:\Users\DeLL\Desktop\boost bot project 8k\rich_boost\venv\Lib\site-packages\sqlalchemy\sql\elements.py", line 517, in _execute_on_connection
    return connection._execute_clauseelement(
           ^^^^^^^^^^^^^^^^^^^^^^^^^^^^^^^^^^
  File "C:\Users\DeLL\Desktop\boost bot project 8k\rich_boost\venv\Lib\site-packages\sqlalchemy\engine\base.py", line 1639, in _execute_clauseelement
    ret = self._execute_context(
          ^^^^^^^^^^^^^^^^^^^^^^
  File "C:\Users\DeLL\Desktop\boost bot project 8k\rich_boost\venv\Lib\site-packages\sqlalchemy\engine\base.py", line 1848, in _execute_context
    return self._exec_single_context(
           ^^^^^^^^^^^^^^^^^^^^^^^^^^
  File "C:\Users\DeLL\Desktop\boost bot project 8k\rich_boost\venv\Lib\site-packages\sqlalchemy\engine\base.py", line 1988, in _exec_single_context
    self._handle_dbapi_exception(
  File "C:\Users\DeLL\Desktop\boost bot project 8k\rich_boost\venv\Lib\site-packages\sqlalchemy\engine\base.py", line 2344, in _handle_dbapi_exception
    raise sqlalchemy_exception.with_traceback(exc_info[2]) from e
  File "C:\Users\DeLL\Desktop\boost bot project 8k\rich_boost\venv\Lib\site-packages\sqlalchemy\engine\base.py", line 1969, in _exec_single_context
    self.dialect.do_execute(
  File "C:\Users\DeLL\Desktop\boost bot project 8k\rich_boost\venv\Lib\site-packages\sqlalchemy\engine\default.py", line 922, in do_execute
    cursor.execute(statement, parameters)
  File "C:\Users\DeLL\Desktop\boost bot project 8k\rich_boost\venv\Lib\site-packages\sqlalchemy\dialects\sqlite\aiosqlite.py", line 146, in execute
    self._adapt_connection._handle_exception(error)
  File "C:\Users\DeLL\Desktop\boost bot project 8k\rich_boost\venv\Lib\site-packages\sqlalchemy\dialects\sqlite\aiosqlite.py", line 298, in _handle_exception
    raise error
  File "C:\Users\DeLL\Desktop\boost bot project 8k\rich_boost\venv\Lib\site-packages\sqlalchemy\dialects\sqlite\aiosqlite.py", line 128, in execute
    self.await_(_cursor.execute(operation, parameters))
  File "C:\Users\DeLL\Desktop\boost bot project 8k\rich_boost\venv\Lib\site-packages\sqlalchemy\util\_concurrency_py3k.py", line 130, in await_only
    return current.driver.switch(awaitable)  # type: ignore[no-any-return]
           ^^^^^^^^^^^^^^^^^^^^^^^^^^^^^^^^
  File "C:\Users\DeLL\Desktop\boost bot project 8k\rich_boost\venv\Lib\site-packages\sqlalchemy\util\_concurrency_py3k.py", line 195, in greenlet_spawn
    value = await result
            ^^^^^^^^^^^^
  File "C:\Users\DeLL\Desktop\boost bot project 8k\rich_boost\venv\Lib\site-packages\aiosqlite\cursor.py", line 40, in execute
    await self._execute(self._cursor.execute, sql, parameters)
  File "C:\Users\DeLL\Desktop\boost bot project 8k\rich_boost\venv\Lib\site-packages\aiosqlite\cursor.py", line 32, in _execute
    return await self._conn._execute(fn, *args, **kwargs)
           ^^^^^^^^^^^^^^^^^^^^^^^^^^^^^^^^^^^^^^^^^^^^^^
  File "C:\Users\DeLL\Desktop\boost bot project 8k\rich_boost\venv\Lib\site-packages\aiosqlite\core.py", line 122, in _execute
    return await future
           ^^^^^^^^^^^^
  File "C:\Users\DeLL\Desktop\boost bot project 8k\rich_boost\venv\Lib\site-packages\aiosqlite\core.py", line 105, in run
    result = function()
             ^^^^^^^^^^
sqlalchemy.exc.OperationalError: (sqlite3.OperationalError) no such table: users
[SQL: SELECT users.id, users.tg_id, users.username, users.region, users.role, users.created_at 
FROM users 
WHERE users.tg_id = ?]
[parameters: (1189473577,)]
(Background on this error at: https://sqlalche.me/e/20/e3q8)
19:59:03 | INFO | aiogram.dispatcher | Polling stopped
19:59:03 | INFO | aiogram.dispatcher | Polling stopped for bot @Rich_boostBot id=7189291350 - 'Rich boost'
19:59:06 | INFO | aiogram.dispatcher | Start polling
19:59:07 | INFO | aiogram.dispatcher | Run polling for bot @Rich_boostBot id=7189291350 - 'Rich boost'
19:59:13 | INFO | app.handlers.common | @soquoru (id=1189473577) –∏—Å–ø–æ–ª—å–∑–æ–≤–∞–ª /start
19:59:14 | INFO | aiogram.event | Update id=424477403 is handled. Duration 421 ms by bot id=7189291350
19:59:51 | INFO | app.handlers.common | @soquoru (id=1189473577) –≤—ã–±—Ä–∞–ª —Ä–µ–≥–∏–æ–Ω: üá∑üá∫ –†–£
19:59:52 | INFO | aiogram.event | Update id=424477404 is handled. Duration 484 ms by bot id=7189291350
19:59:55 | INFO | app.handlers.common | @soquoru (id=1189473577) –≤—ã–±—Ä–∞–ª —Ä–µ–≥–∏–æ–Ω: üá∞üáø –ö–ó
19:59:55 | INFO | aiogram.event | Update id=424477405 is handled. Duration 172 ms by bot id=7189291350
19:59:59 | INFO | app.handlers.common | @soquoru (id=1189473577) –≤—ã–±—Ä–∞–ª —Ä–µ–≥–∏–æ–Ω: üá∞üá¨ –ö–†
19:59:59 | INFO | aiogram.event | Update id=424477406 is handled. Duration 157 ms by bot id=7189291350
20:00:02 | INFO | app.handlers.common | @soquoru (id=1189473577) –≤—ã–±—Ä–∞–ª —Ä–µ–≥–∏–æ–Ω: üåê –ö—Ä–∏–ø—Ç–∞
20:00:02 | INFO | aiogram.event | Update id=424477407 is handled. Duration 156 ms by bot id=7189291350
20:00:26 | INFO | aiogram.dispatcher | Polling stopped
20:00:27 | INFO | aiogram.dispatcher | Polling stopped for bot @Rich_boostBot id=7189291350 - 'Rich boost'
20:00:31 | INFO | aiogram.dispatcher | Start polling
20:00:31 | INFO | aiogram.dispatcher | Run polling for bot @Rich_boostBot id=7189291350 - 'Rich boost'
20:00:33 | INFO | app.handlers.common | @soquoru (id=1189473577) –≤—ã–±—Ä–∞–ª —Ä–µ–≥–∏–æ–Ω: üåê –ö—Ä–∏–ø—Ç–∞
20:00:33 | INFO | aiogram.event | Update id=424477408 is handled. Duration 452 ms by bot id=7189291350
20:00:41 | INFO | app.handlers.common | @soquoru (id=1189473577) –≤—ã–±—Ä–∞–ª —Ä–µ–≥–∏–æ–Ω: üá∞üá¨ –ö–†
20:00:41 | INFO | aiogram.event | Update id=424477409 is handled. Duration 155 ms by bot id=7189291350
20:00:49 | INFO | app.handlers.common | @soquoru (id=1189473577) –∏—Å–ø–æ–ª—å–∑–æ–≤–∞–ª /start
20:00:49 | INFO | aiogram.event | Update id=424477410 is handled. Duration 233 ms by bot id=7189291350
20:06:19 | INFO | aiogram.dispatcher | Polling stopped
20:06:19 | INFO | aiogram.dispatcher | Polling stopped for bot @Rich_boostBot id=7189291350 - 'Rich boost'
20:06:23 | INFO | aiogram.dispatcher | Start polling
20:06:24 | INFO | aiogram.dispatcher | Run polling for bot @Rich_boostBot id=7189291350 - 'Rich boost'
20:06:32 | INFO | app.handlers.common | @soquoru (id=1189473577) –ø–æ–≤—Ç–æ—Ä–Ω–æ –∏—Å–ø–æ–ª—å–∑–æ–≤–∞–ª /start
20:06:33 | INFO | aiogram.event | Update id=424477411 is handled. Duration 390 ms by bot id=7189291350
20:06:45 | INFO | app.handlers.common | @soquoru (id=1189473577) –ø–æ–≤—Ç–æ—Ä–Ω–æ –∏—Å–ø–æ–ª—å–∑–æ–≤–∞–ª /start
20:06:45 | INFO | aiogram.event | Update id=424477412 is handled. Duration 219 ms by bot id=7189291350
20:07:06 | INFO | app.handlers.common | @soquoru (id=1189473577) –∑–∞—Ä–µ–≥–∏—Å—Ç—Ä–∏—Ä–æ–≤–∞–ª—Å—è —á–µ—Ä–µ–∑ /start
20:07:06 | INFO | aiogram.event | Update id=424477413 is handled. Duration 421 ms by bot id=7189291350
20:07:17 | INFO | app.handlers.common | @soquoru (id=1189473577) –≤—ã–±—Ä–∞–ª —Ä–µ–≥–∏–æ–Ω: üá∞üá¨ –ö–†
20:07:18 | INFO | aiogram.event | Update id=424477414 is handled. Duration 187 ms by bot id=7189291350
20:08:40 | INFO | aiogram.dispatcher | Polling stopped
20:08:40 | INFO | aiogram.dispatcher | Polling stopped for bot @Rich_boostBot id=7189291350 - 'Rich boost'
20:08:44 | INFO | aiogram.dispatcher | Start polling
20:08:45 | INFO | aiogram.dispatcher | Run polling for bot @Rich_boostBot id=7189291350 - 'Rich boost'
20:08:56 | INFO | aiogram.event | Update id=424477415 is not handled. Duration 16 ms by bot id=7189291350
20:08:56 | ERROR | aiogram.event | Cause exception while process update id=424477415 by bot id=7189291350
OperationalError: (sqlite3.OperationalError) no such column: users.name
[SQL: SELECT users.id, users.tg_id, users.name, users.region, users.role, users.created_at 
FROM users 
WHERE users.tg_id = ?]
[parameters: (1189473577,)]
(Background on this error at: https://sqlalche.me/e/20/e3q8)
Traceback (most recent call last):
  File "C:\Users\DeLL\Desktop\boost bot project 8k\rich_boost\venv\Lib\site-packages\sqlalchemy\engine\base.py", line 1969, in _exec_single_context
    self.dialect.do_execute(
  File "C:\Users\DeLL\Desktop\boost bot project 8k\rich_boost\venv\Lib\site-packages\sqlalchemy\engine\default.py", line 922, in do_execute
    cursor.execute(statement, parameters)
  File "C:\Users\DeLL\Desktop\boost bot project 8k\rich_boost\venv\Lib\site-packages\sqlalchemy\dialects\sqlite\aiosqlite.py", line 146, in execute
    self._adapt_connection._handle_exception(error)
  File "C:\Users\DeLL\Desktop\boost bot project 8k\rich_boost\venv\Lib\site-packages\sqlalchemy\dialects\sqlite\aiosqlite.py", line 298, in _handle_exception
    raise error
  File "C:\Users\DeLL\Desktop\boost bot project 8k\rich_boost\venv\Lib\site-packages\sqlalchemy\dialects\sqlite\aiosqlite.py", line 128, in execute
    self.await_(_cursor.execute(operation, parameters))
  File "C:\Users\DeLL\Desktop\boost bot project 8k\rich_boost\venv\Lib\site-packages\sqlalchemy\util\_concurrency_py3k.py", line 130, in await_only
    return current.driver.switch(awaitable)  # type: ignore[no-any-return]
           ^^^^^^^^^^^^^^^^^^^^^^^^^^^^^^^^
  File "C:\Users\DeLL\Desktop\boost bot project 8k\rich_boost\venv\Lib\site-packages\sqlalchemy\util\_concurrency_py3k.py", line 195, in greenlet_spawn
    value = await result
            ^^^^^^^^^^^^
  File "C:\Users\DeLL\Desktop\boost bot project 8k\rich_boost\venv\Lib\site-packages\aiosqlite\cursor.py", line 40, in execute
    await self._execute(self._cursor.execute, sql, parameters)
  File "C:\Users\DeLL\Desktop\boost bot project 8k\rich_boost\venv\Lib\site-packages\aiosqlite\cursor.py", line 32, in _execute
    return await self._conn._execute(fn, *args, **kwargs)
           ^^^^^^^^^^^^^^^^^^^^^^^^^^^^^^^^^^^^^^^^^^^^^^
  File "C:\Users\DeLL\Desktop\boost bot project 8k\rich_boost\venv\Lib\site-packages\aiosqlite\core.py", line 122, in _execute
    return await future
           ^^^^^^^^^^^^
  File "C:\Users\DeLL\Desktop\boost bot project 8k\rich_boost\venv\Lib\site-packages\aiosqlite\core.py", line 105, in run
    result = function()
             ^^^^^^^^^^
sqlite3.OperationalError: no such column: users.name

The above exception was the direct cause of the following exception:

Traceback (most recent call last):
  File "C:\Users\DeLL\Desktop\boost bot project 8k\rich_boost\venv\Lib\site-packages\aiogram\dispatcher\dispatcher.py", line 309, in _process_update
    response = await self.feed_update(bot, update, **kwargs)
               ^^^^^^^^^^^^^^^^^^^^^^^^^^^^^^^^^^^^^^^^^^^^^
  File "C:\Users\DeLL\Desktop\boost bot project 8k\rich_boost\venv\Lib\site-packages\aiogram\dispatcher\dispatcher.py", line 158, in feed_update
    response = await self.update.wrap_outer_middleware(
               ^^^^^^^^^^^^^^^^^^^^^^^^^^^^^^^^^^^^^^^^
  File "C:\Users\DeLL\Desktop\boost bot project 8k\rich_boost\venv\Lib\site-packages\aiogram\dispatcher\middlewares\error.py", line 25, in __call__
    return await handler(event, data)
           ^^^^^^^^^^^^^^^^^^^^^^^^^^
  File "C:\Users\DeLL\Desktop\boost bot project 8k\rich_boost\venv\Lib\site-packages\aiogram\dispatcher\middlewares\user_context.py", line 27, in __call__
    return await handler(event, data)
           ^^^^^^^^^^^^^^^^^^^^^^^^^^
  File "C:\Users\DeLL\Desktop\boost bot project 8k\rich_boost\venv\Lib\site-packages\aiogram\fsm\middleware.py", line 41, in __call__
    return await handler(event, data)
           ^^^^^^^^^^^^^^^^^^^^^^^^^^
  File "C:\Users\DeLL\Desktop\boost bot project 8k\rich_boost\venv\Lib\site-packages\aiogram\dispatcher\event\telegram.py", line 121, in trigger
    return await wrapped_inner(event, kwargs)
           ^^^^^^^^^^^^^^^^^^^^^^^^^^^^^^^^^^
  File "C:\Users\DeLL\Desktop\boost bot project 8k\rich_boost\venv\Lib\site-packages\aiogram\dispatcher\event\handler.py", line 43, in call
    return await wrapped()
           ^^^^^^^^^^^^^^^
  File "C:\Users\DeLL\Desktop\boost bot project 8k\rich_boost\venv\Lib\site-packages\aiogram\dispatcher\dispatcher.py", line 276, in _listen_update
    return await self.propagate_event(update_type=update_type, event=event, **kwargs)
           ^^^^^^^^^^^^^^^^^^^^^^^^^^^^^^^^^^^^^^^^^^^^^^^^^^^^^^^^^^^^^^^^^^^^^^^^^^
  File "C:\Users\DeLL\Desktop\boost bot project 8k\rich_boost\venv\Lib\site-packages\aiogram\dispatcher\router.py", line 128, in propagate_event
    return await observer.wrap_outer_middleware(_wrapped, event=event, data=kwargs)
           ^^^^^^^^^^^^^^^^^^^^^^^^^^^^^^^^^^^^^^^^^^^^^^^^^^^^^^^^^^^^^^^^^^^^^^^^
  File "C:\Users\DeLL\Desktop\boost bot project 8k\rich_boost\venv\Lib\site-packages\aiogram\dispatcher\router.py", line 123, in _wrapped
    return await self._propagate_event(
           ^^^^^^^^^^^^^^^^^^^^^^^^^^^^
  File "C:\Users\DeLL\Desktop\boost bot project 8k\rich_boost\venv\Lib\site-packages\aiogram\dispatcher\router.py", line 156, in _propagate_event
    response = await router.propagate_event(update_type=update_type, event=event, **kwargs)
               ^^^^^^^^^^^^^^^^^^^^^^^^^^^^^^^^^^^^^^^^^^^^^^^^^^^^^^^^^^^^^^^^^^^^^^^^^^^^
  File "C:\Users\DeLL\Desktop\boost bot project 8k\rich_boost\venv\Lib\site-packages\aiogram\dispatcher\router.py", line 128, in propagate_event
    return await observer.wrap_outer_middleware(_wrapped, event=event, data=kwargs)
           ^^^^^^^^^^^^^^^^^^^^^^^^^^^^^^^^^^^^^^^^^^^^^^^^^^^^^^^^^^^^^^^^^^^^^^^^
  File "C:\Users\DeLL\Desktop\boost bot project 8k\rich_boost\venv\Lib\site-packages\aiogram\dispatcher\router.py", line 123, in _wrapped
    return await self._propagate_event(
           ^^^^^^^^^^^^^^^^^^^^^^^^^^^^
  File "C:\Users\DeLL\Desktop\boost bot project 8k\rich_boost\venv\Lib\site-packages\aiogram\dispatcher\router.py", line 148, in _propagate_event
    response = await observer.trigger(event, **kwargs)
               ^^^^^^^^^^^^^^^^^^^^^^^^^^^^^^^^^^^^^^^
  File "C:\Users\DeLL\Desktop\boost bot project 8k\rich_boost\venv\Lib\site-packages\aiogram\dispatcher\event\telegram.py", line 121, in trigger
    return await wrapped_inner(event, kwargs)
           ^^^^^^^^^^^^^^^^^^^^^^^^^^^^^^^^^^
  File "C:\Users\DeLL\Desktop\boost bot project 8k\rich_boost\venv\Lib\site-packages\aiogram\dispatcher\event\handler.py", line 43, in call
    return await wrapped()
           ^^^^^^^^^^^^^^^
  File "C:\Users\DeLL\Desktop\boost bot project 8k\rich_boost\app\handlers\common.py", line 12, in cmd_start
    user = await get_user_by_tg_id(message.from_user.id)
           ^^^^^^^^^^^^^^^^^^^^^^^^^^^^^^^^^^^^^^^^^^^^^
  File "C:\Users\DeLL\Desktop\boost bot project 8k\rich_boost\app\database\crud.py", line 29, in get_user_by_tg_id
    result = await session.execute(select(User).where(User.tg_id == tg_id))
             ^^^^^^^^^^^^^^^^^^^^^^^^^^^^^^^^^^^^^^^^^^^^^^^^^^^^^^^^^^^^^^
  File "C:\Users\DeLL\Desktop\boost bot project 8k\rich_boost\venv\Lib\site-packages\sqlalchemy\ext\asyncio\session.py", line 455, in execute
    result = await greenlet_spawn(
             ^^^^^^^^^^^^^^^^^^^^^
  File "C:\Users\DeLL\Desktop\boost bot project 8k\rich_boost\venv\Lib\site-packages\sqlalchemy\util\_concurrency_py3k.py", line 200, in greenlet_spawn
    result = context.throw(*sys.exc_info())
             ^^^^^^^^^^^^^^^^^^^^^^^^^^^^^^
  File "C:\Users\DeLL\Desktop\boost bot project 8k\rich_boost\venv\Lib\site-packages\sqlalchemy\orm\session.py", line 2308, in execute
    return self._execute_internal(
           ^^^^^^^^^^^^^^^^^^^^^^^
  File "C:\Users\DeLL\Desktop\boost bot project 8k\rich_boost\venv\Lib\site-packages\sqlalchemy\orm\session.py", line 2190, in _execute_internal
    result: Result[Any] = compile_state_cls.orm_execute_statement(
                          ^^^^^^^^^^^^^^^^^^^^^^^^^^^^^^^^^^^^^^^^
  File "C:\Users\DeLL\Desktop\boost bot project 8k\rich_boost\venv\Lib\site-packages\sqlalchemy\orm\context.py", line 293, in orm_execute_statement
    result = conn.execute(
             ^^^^^^^^^^^^^
  File "C:\Users\DeLL\Desktop\boost bot project 8k\rich_boost\venv\Lib\site-packages\sqlalchemy\engine\base.py", line 1416, in execute
    return meth(
           ^^^^^
  File "C:\Users\DeLL\Desktop\boost bot project 8k\rich_boost\venv\Lib\site-packages\sqlalchemy\sql\elements.py", line 517, in _execute_on_connection
    return connection._execute_clauseelement(
           ^^^^^^^^^^^^^^^^^^^^^^^^^^^^^^^^^^
  File "C:\Users\DeLL\Desktop\boost bot project 8k\rich_boost\venv\Lib\site-packages\sqlalchemy\engine\base.py", line 1639, in _execute_clauseelement
    ret = self._execute_context(
          ^^^^^^^^^^^^^^^^^^^^^^
  File "C:\Users\DeLL\Desktop\boost bot project 8k\rich_boost\venv\Lib\site-packages\sqlalchemy\engine\base.py", line 1848, in _execute_context
    return self._exec_single_context(
           ^^^^^^^^^^^^^^^^^^^^^^^^^^
  File "C:\Users\DeLL\Desktop\boost bot project 8k\rich_boost\venv\Lib\site-packages\sqlalchemy\engine\base.py", line 1988, in _exec_single_context
    self._handle_dbapi_exception(
  File "C:\Users\DeLL\Desktop\boost bot project 8k\rich_boost\venv\Lib\site-packages\sqlalchemy\engine\base.py", line 2344, in _handle_dbapi_exception
    raise sqlalchemy_exception.with_traceback(exc_info[2]) from e
  File "C:\Users\DeLL\Desktop\boost bot project 8k\rich_boost\venv\Lib\site-packages\sqlalchemy\engine\base.py", line 1969, in _exec_single_context
    self.dialect.do_execute(
  File "C:\Users\DeLL\Desktop\boost bot project 8k\rich_boost\venv\Lib\site-packages\sqlalchemy\engine\default.py", line 922, in do_execute
    cursor.execute(statement, parameters)
  File "C:\Users\DeLL\Desktop\boost bot project 8k\rich_boost\venv\Lib\site-packages\sqlalchemy\dialects\sqlite\aiosqlite.py", line 146, in execute
    self._adapt_connection._handle_exception(error)
  File "C:\Users\DeLL\Desktop\boost bot project 8k\rich_boost\venv\Lib\site-packages\sqlalchemy\dialects\sqlite\aiosqlite.py", line 298, in _handle_exception
    raise error
  File "C:\Users\DeLL\Desktop\boost bot project 8k\rich_boost\venv\Lib\site-packages\sqlalchemy\dialects\sqlite\aiosqlite.py", line 128, in execute
    self.await_(_cursor.execute(operation, parameters))
  File "C:\Users\DeLL\Desktop\boost bot project 8k\rich_boost\venv\Lib\site-packages\sqlalchemy\util\_concurrency_py3k.py", line 130, in await_only
    return current.driver.switch(awaitable)  # type: ignore[no-any-return]
           ^^^^^^^^^^^^^^^^^^^^^^^^^^^^^^^^
  File "C:\Users\DeLL\Desktop\boost bot project 8k\rich_boost\venv\Lib\site-packages\sqlalchemy\util\_concurrency_py3k.py", line 195, in greenlet_spawn
    value = await result
            ^^^^^^^^^^^^
  File "C:\Users\DeLL\Desktop\boost bot project 8k\rich_boost\venv\Lib\site-packages\aiosqlite\cursor.py", line 40, in execute
    await self._execute(self._cursor.execute, sql, parameters)
  File "C:\Users\DeLL\Desktop\boost bot project 8k\rich_boost\venv\Lib\site-packages\aiosqlite\cursor.py", line 32, in _execute
    return await self._conn._execute(fn, *args, **kwargs)
           ^^^^^^^^^^^^^^^^^^^^^^^^^^^^^^^^^^^^^^^^^^^^^^
  File "C:\Users\DeLL\Desktop\boost bot project 8k\rich_boost\venv\Lib\site-packages\aiosqlite\core.py", line 122, in _execute
    return await future
           ^^^^^^^^^^^^
  File "C:\Users\DeLL\Desktop\boost bot project 8k\rich_boost\venv\Lib\site-packages\aiosqlite\core.py", line 105, in run
    result = function()
             ^^^^^^^^^^
sqlalchemy.exc.OperationalError: (sqlite3.OperationalError) no such column: users.name
[SQL: SELECT users.id, users.tg_id, users.name, users.region, users.role, users.created_at 
FROM users 
WHERE users.tg_id = ?]
[parameters: (1189473577,)]
(Background on this error at: https://sqlalche.me/e/20/e3q8)
20:09:29 | INFO | aiogram.dispatcher | Polling stopped
20:09:29 | INFO | aiogram.dispatcher | Polling stopped for bot @Rich_boostBot id=7189291350 - 'Rich boost'
20:09:34 | INFO | aiogram.dispatcher | Start polling
20:09:34 | INFO | aiogram.dispatcher | Run polling for bot @Rich_boostBot id=7189291350 - 'Rich boost'
20:09:45 | INFO | aiogram.event | Update id=424477416 is not handled. Duration 15 ms by bot id=7189291350
20:09:45 | ERROR | aiogram.event | Cause exception while process update id=424477416 by bot id=7189291350
TypeError: add_user() got an unexpected keyword argument 'name'
Traceback (most recent call last):
  File "C:\Users\DeLL\Desktop\boost bot project 8k\rich_boost\venv\Lib\site-packages\aiogram\dispatcher\dispatcher.py", line 309, in _process_update
    response = await self.feed_update(bot, update, **kwargs)
               ^^^^^^^^^^^^^^^^^^^^^^^^^^^^^^^^^^^^^^^^^^^^^
  File "C:\Users\DeLL\Desktop\boost bot project 8k\rich_boost\venv\Lib\site-packages\aiogram\dispatcher\dispatcher.py", line 158, in feed_update
    response = await self.update.wrap_outer_middleware(
               ^^^^^^^^^^^^^^^^^^^^^^^^^^^^^^^^^^^^^^^^
  File "C:\Users\DeLL\Desktop\boost bot project 8k\rich_boost\venv\Lib\site-packages\aiogram\dispatcher\middlewares\error.py", line 25, in __call__
    return await handler(event, data)
           ^^^^^^^^^^^^^^^^^^^^^^^^^^
  File "C:\Users\DeLL\Desktop\boost bot project 8k\rich_boost\venv\Lib\site-packages\aiogram\dispatcher\middlewares\user_context.py", line 27, in __call__
    return await handler(event, data)
           ^^^^^^^^^^^^^^^^^^^^^^^^^^
  File "C:\Users\DeLL\Desktop\boost bot project 8k\rich_boost\venv\Lib\site-packages\aiogram\fsm\middleware.py", line 41, in __call__
    return await handler(event, data)
           ^^^^^^^^^^^^^^^^^^^^^^^^^^
  File "C:\Users\DeLL\Desktop\boost bot project 8k\rich_boost\venv\Lib\site-packages\aiogram\dispatcher\event\telegram.py", line 121, in trigger
    return await wrapped_inner(event, kwargs)
           ^^^^^^^^^^^^^^^^^^^^^^^^^^^^^^^^^^
  File "C:\Users\DeLL\Desktop\boost bot project 8k\rich_boost\venv\Lib\site-packages\aiogram\dispatcher\event\handler.py", line 43, in call
    return await wrapped()
           ^^^^^^^^^^^^^^^
  File "C:\Users\DeLL\Desktop\boost bot project 8k\rich_boost\venv\Lib\site-packages\aiogram\dispatcher\dispatcher.py", line 276, in _listen_update
    return await self.propagate_event(update_type=update_type, event=event, **kwargs)
           ^^^^^^^^^^^^^^^^^^^^^^^^^^^^^^^^^^^^^^^^^^^^^^^^^^^^^^^^^^^^^^^^^^^^^^^^^^
  File "C:\Users\DeLL\Desktop\boost bot project 8k\rich_boost\venv\Lib\site-packages\aiogram\dispatcher\router.py", line 128, in propagate_event
    return await observer.wrap_outer_middleware(_wrapped, event=event, data=kwargs)
           ^^^^^^^^^^^^^^^^^^^^^^^^^^^^^^^^^^^^^^^^^^^^^^^^^^^^^^^^^^^^^^^^^^^^^^^^
  File "C:\Users\DeLL\Desktop\boost bot project 8k\rich_boost\venv\Lib\site-packages\aiogram\dispatcher\router.py", line 123, in _wrapped
    return await self._propagate_event(
           ^^^^^^^^^^^^^^^^^^^^^^^^^^^^
  File "C:\Users\DeLL\Desktop\boost bot project 8k\rich_boost\venv\Lib\site-packages\aiogram\dispatcher\router.py", line 156, in _propagate_event
    response = await router.propagate_event(update_type=update_type, event=event, **kwargs)
               ^^^^^^^^^^^^^^^^^^^^^^^^^^^^^^^^^^^^^^^^^^^^^^^^^^^^^^^^^^^^^^^^^^^^^^^^^^^^
  File "C:\Users\DeLL\Desktop\boost bot project 8k\rich_boost\venv\Lib\site-packages\aiogram\dispatcher\router.py", line 128, in propagate_event
    return await observer.wrap_outer_middleware(_wrapped, event=event, data=kwargs)
           ^^^^^^^^^^^^^^^^^^^^^^^^^^^^^^^^^^^^^^^^^^^^^^^^^^^^^^^^^^^^^^^^^^^^^^^^
  File "C:\Users\DeLL\Desktop\boost bot project 8k\rich_boost\venv\Lib\site-packages\aiogram\dispatcher\router.py", line 123, in _wrapped
    return await self._propagate_event(
           ^^^^^^^^^^^^^^^^^^^^^^^^^^^^
  File "C:\Users\DeLL\Desktop\boost bot project 8k\rich_boost\venv\Lib\site-packages\aiogram\dispatcher\router.py", line 148, in _propagate_event
    response = await observer.trigger(event, **kwargs)
               ^^^^^^^^^^^^^^^^^^^^^^^^^^^^^^^^^^^^^^^
  File "C:\Users\DeLL\Desktop\boost bot project 8k\rich_boost\venv\Lib\site-packages\aiogram\dispatcher\event\telegram.py", line 121, in trigger
    return await wrapped_inner(event, kwargs)
           ^^^^^^^^^^^^^^^^^^^^^^^^^^^^^^^^^^
  File "C:\Users\DeLL\Desktop\boost bot project 8k\rich_boost\venv\Lib\site-packages\aiogram\dispatcher\event\handler.py", line 43, in call
    return await wrapped()
           ^^^^^^^^^^^^^^^
  File "C:\Users\DeLL\Desktop\boost bot project 8k\rich_boost\app\handlers\common.py", line 17, in cmd_start
    await add_user(
          ^^^^^^^^^
TypeError: add_user() got an unexpected keyword argument 'name'
20:10:41 | INFO | aiogram.dispatcher | Polling stopped
20:10:42 | INFO | aiogram.dispatcher | Polling stopped for bot @Rich_boostBot id=7189291350 - 'Rich boost'
20:10:46 | INFO | aiogram.dispatcher | Start polling
20:10:46 | INFO | aiogram.dispatcher | Run polling for bot @Rich_boostBot id=7189291350 - 'Rich boost'
20:10:48 | INFO | app.handlers.common | @soquoru (id=1189473577) –∑–∞—Ä–µ–≥–∏—Å—Ç—Ä–∏—Ä–æ–≤–∞–ª—Å—è —á–µ—Ä–µ–∑ /start
20:10:49 | INFO | aiogram.event | Update id=424477417 is handled. Duration 516 ms by bot id=7189291350
20:10:50 | INFO | app.handlers.common | @soquoru (id=1189473577) –≤—ã–±—Ä–∞–ª —Ä–µ–≥–∏–æ–Ω: üá∑üá∫ –†–£
20:10:51 | INFO | aiogram.event | Update id=424477418 is handled. Duration 171 ms by bot id=7189291350
20:11:08 | INFO | app.handlers.common | @soquoru (id=1189473577) –≤—ã–±—Ä–∞–ª —Ä–µ–≥–∏–æ–Ω: üá∞üá¨ –ö–†
20:11:08 | INFO | aiogram.event | Update id=424477419 is handled. Duration 375 ms by bot id=7189291350
20:17:29 | INFO | aiogram.dispatcher | Polling stopped
20:17:29 | INFO | aiogram.dispatcher | Polling stopped for bot @Rich_boostBot id=7189291350 - 'Rich boost'
20:17:33 | INFO | aiogram.dispatcher | Start polling
20:17:33 | INFO | aiogram.dispatcher | Run polling for bot @Rich_boostBot id=7189291350 - 'Rich boost'
20:19:07 | INFO | aiogram.dispatcher | Polling stopped
20:19:07 | INFO | aiogram.dispatcher | Polling stopped for bot @Rich_boostBot id=7189291350 - 'Rich boost'
20:19:12 | INFO | aiogram.dispatcher | Start polling
20:19:12 | INFO | aiogram.dispatcher | Run polling for bot @Rich_boostBot id=7189291350 - 'Rich boost'
20:19:20 | INFO | aiogram.dispatcher | Polling stopped
20:19:21 | INFO | aiogram.dispatcher | Polling stopped for bot @Rich_boostBot id=7189291350 - 'Rich boost'
20:19:25 | INFO | aiogram.dispatcher | Start polling
20:19:25 | INFO | aiogram.dispatcher | Run polling for bot @Rich_boostBot id=7189291350 - 'Rich boost'
20:19:29 | INFO | app.handlers.common | @soquoru (id=1189473577) –ø–æ–≤—Ç–æ—Ä–Ω–æ –∏—Å–ø–æ–ª—å–∑–æ–≤–∞–ª /start
20:19:30 | INFO | aiogram.event | Update id=424477420 is handled. Duration 1000 ms by bot id=7189291350
20:19:33 | INFO | aiogram.event | Update id=424477421 is not handled. Duration 0 ms by bot id=7189291350
20:19:49 | INFO | app.handlers.common | @soquoru (id=1189473577) –ø–æ–≤—Ç–æ—Ä–Ω–æ –∏—Å–ø–æ–ª—å–∑–æ–≤–∞–ª /start
20:19:50 | INFO | aiogram.event | Update id=424477422 is handled. Duration 391 ms by bot id=7189291350
20:20:15 | ERROR | aiogram.dispatcher | Failed to fetch updates - TelegramNetworkError: HTTP Client says - ClientOSError: [WinError 1236] –ü–æ–¥–∫–ª—é—á–µ–Ω–∏–µ –∫ —Å–µ—Ç–∏ –±—ã–ª–æ —Ä–∞–∑–æ—Ä–≤–∞–Ω–æ –ª–æ–∫–∞–ª—å–Ω–æ–π —Å–∏—Å—Ç–µ–º–æ–π
20:20:15 | WARNING | aiogram.dispatcher | Sleep for 1.000000 seconds and try again... (tryings = 0, bot id = 7189291350)
20:20:16 | ERROR | aiogram.dispatcher | Failed to fetch updates - TelegramNetworkError: HTTP Client says - ClientConnectorError: Cannot connect to host api.telegram.org:443 ssl:default [getaddrinfo failed]
20:20:16 | WARNING | aiogram.dispatcher | Sleep for 1.543294 seconds and try again... (tryings = 1, bot id = 7189291350)
20:20:17 | ERROR | aiogram.dispatcher | Failed to fetch updates - TelegramNetworkError: HTTP Client says - ClientConnectorError: Cannot connect to host api.telegram.org:443 ssl:default [getaddrinfo failed]
20:20:17 | WARNING | aiogram.dispatcher | Sleep for 1.876597 seconds and try again... (tryings = 2, bot id = 7189291350)
20:20:19 | ERROR | aiogram.dispatcher | Failed to fetch updates - TelegramNetworkError: HTTP Client says - ClientConnectorError: Cannot connect to host api.telegram.org:443 ssl:default [getaddrinfo failed]
20:20:19 | WARNING | aiogram.dispatcher | Sleep for 2.338945 seconds and try again... (tryings = 3, bot id = 7189291350)
20:20:22 | ERROR | aiogram.dispatcher | Failed to fetch updates - TelegramNetworkError: HTTP Client says - ClientConnectorError: Cannot connect to host api.telegram.org:443 ssl:default [getaddrinfo failed]
20:20:22 | WARNING | aiogram.dispatcher | Sleep for 3.019469 seconds and try again... (tryings = 4, bot id = 7189291350)
20:20:25 | ERROR | aiogram.dispatcher | Failed to fetch updates - TelegramNetworkError: HTTP Client says - ClientConnectorError: Cannot connect to host api.telegram.org:443 ssl:default [getaddrinfo failed]
20:20:25 | WARNING | aiogram.dispatcher | Sleep for 3.820525 seconds and try again... (tryings = 5, bot id = 7189291350)
20:20:28 | ERROR | aiogram.dispatcher | Failed to fetch updates - TelegramNetworkError: HTTP Client says - ClientConnectorError: Cannot connect to host api.telegram.org:443 ssl:default [getaddrinfo failed]
20:20:28 | WARNING | aiogram.dispatcher | Sleep for 4.978600 seconds and try again... (tryings = 6, bot id = 7189291350)
20:20:44 | INFO | aiogram.dispatcher | Connection established (tryings = 7, bot id = 7189291350)
21:08:42 | ERROR | aiogram.dispatcher | Failed to fetch updates - TelegramNetworkError: HTTP Client says - Request timeout error
21:08:42 | WARNING | aiogram.dispatcher | Sleep for 1.000000 seconds and try again... (tryings = 0, bot id = 7189291350)
21:08:44 | INFO | aiogram.dispatcher | Connection established (tryings = 1, bot id = 7189291350)
21:08:44 | INFO | aiogram.event | Update id=424477423 is not handled. Duration 0 ms by bot id=7189291350
21:08:44 | INFO | app.handlers.common | @soquoru (id=1189473577) –ø–æ–≤—Ç–æ—Ä–Ω–æ –∏—Å–ø–æ–ª—å–∑–æ–≤–∞–ª /start
21:08:46 | INFO | aiogram.event | Update id=424477424 is handled. Duration 1891 ms by bot id=7189291350
02:12:14 | ERROR | aiogram.dispatcher | Failed to fetch updates - TelegramNetworkError: HTTP Client says - Request timeout error
02:12:14 | WARNING | aiogram.dispatcher | Sleep for 1.000000 seconds and try again... (tryings = 0, bot id = 7189291350)
02:12:26 | INFO | aiogram.dispatcher | Connection established (tryings = 1, bot id = 7189291350)
03:01:23 | ERROR | aiogram.dispatcher | Failed to fetch updates - TelegramNetworkError: HTTP Client says - Request timeout error
03:01:23 | WARNING | aiogram.dispatcher | Sleep for 1.000000 seconds and try again... (tryings = 0, bot id = 7189291350)
07:25:28 | ERROR | aiogram.dispatcher | Failed to fetch updates - TelegramNetworkError: HTTP Client says - Request timeout error
07:25:28 | WARNING | aiogram.dispatcher | Sleep for 1.265020 seconds and try again... (tryings = 1, bot id = 7189291350)
07:25:40 | INFO | aiogram.dispatcher | Connection established (tryings = 2, bot id = 7189291350)
13:10:26 | ERROR | aiogram.dispatcher | Failed to fetch updates - TelegramNetworkError: HTTP Client says - Request timeout error
13:10:26 | WARNING | aiogram.dispatcher | Sleep for 1.000000 seconds and try again... (tryings = 0, bot id = 7189291350)
13:10:38 | INFO | aiogram.dispatcher | Connection established (tryings = 1, bot id = 7189291350)
18:29:05 | ERROR | aiogram.dispatcher | Failed to fetch updates - TelegramNetworkError: HTTP Client says - Request timeout error
18:29:05 | WARNING | aiogram.dispatcher | Sleep for 1.000000 seconds and try again... (tryings = 0, bot id = 7189291350)
18:29:18 | INFO | aiogram.dispatcher | Connection established (tryings = 1, bot id = 7189291350)
01:09:08 | ERROR | aiogram.dispatcher | Failed to fetch updates - TelegramNetworkError: HTTP Client says - Request timeout error
01:09:08 | WARNING | aiogram.dispatcher | Sleep for 1.000000 seconds and try again... (tryings = 0, bot id = 7189291350)
01:09:19 | INFO | aiogram.dispatcher | Connection established (tryings = 1, bot id = 7189291350)
06:18:15 | ERROR | aiogram.dispatcher | Failed to fetch updates - TelegramNetworkError: HTTP Client says - Request timeout error
06:18:15 | WARNING | aiogram.dispatcher | Sleep for 1.000000 seconds and try again... (tryings = 0, bot id = 7189291350)
06:18:27 | INFO | aiogram.dispatcher | Connection established (tryings = 1, bot id = 7189291350)
13:09:34 | ERROR | aiogram.dispatcher | Failed to fetch updates - TelegramNetworkError: HTTP Client says - Request timeout error
13:09:34 | WARNING | aiogram.dispatcher | Sleep for 1.000000 seconds and try again... (tryings = 0, bot id = 7189291350)
13:09:45 | INFO | aiogram.dispatcher | Connection established (tryings = 1, bot id = 7189291350)
15:48:03 | ERROR | aiogram.dispatcher | Failed to fetch updates - TelegramNetworkError: HTTP Client says - Request timeout error
15:48:03 | WARNING | aiogram.dispatcher | Sleep for 1.000000 seconds and try again... (tryings = 0, bot id = 7189291350)
15:48:15 | ERROR | aiogram.dispatcher | Failed to fetch updates - TelegramNetworkError: HTTP Client says - ClientConnectorError: Cannot connect to host api.telegram.org:443 ssl:default [getaddrinfo failed]
15:48:15 | WARNING | aiogram.dispatcher | Sleep for 1.420270 seconds and try again... (tryings = 1, bot id = 7189291350)
15:48:28 | ERROR | aiogram.dispatcher | Failed to fetch updates - TelegramNetworkError: HTTP Client says - ClientConnectorError: Cannot connect to host api.telegram.org:443 ssl:default [getaddrinfo failed]
15:48:28 | WARNING | aiogram.dispatcher | Sleep for 1.855176 seconds and try again... (tryings = 2, bot id = 7189291350)
15:48:30 | ERROR | aiogram.dispatcher | Failed to fetch updates - TelegramNetworkError: HTTP Client says - ClientConnectorError: Cannot connect to host api.telegram.org:443 ssl:default [getaddrinfo failed]
15:48:30 | WARNING | aiogram.dispatcher | Sleep for 2.442098 seconds and try again... (tryings = 3, bot id = 7189291350)
15:48:32 | ERROR | aiogram.dispatcher | Failed to fetch updates - TelegramNetworkError: HTTP Client says - ClientConnectorError: Cannot connect to host api.telegram.org:443 ssl:default [getaddrinfo failed]
15:48:32 | WARNING | aiogram.dispatcher | Sleep for 3.341772 seconds and try again... (tryings = 4, bot id = 7189291350)
15:48:35 | ERROR | aiogram.dispatcher | Failed to fetch updates - TelegramNetworkError: HTTP Client says - ClientConnectorError: Cannot connect to host api.telegram.org:443 ssl:default [getaddrinfo failed]
15:48:35 | WARNING | aiogram.dispatcher | Sleep for 4.380035 seconds and try again... (tryings = 5, bot id = 7189291350)
15:48:40 | ERROR | aiogram.dispatcher | Failed to fetch updates - TelegramNetworkError: HTTP Client says - ClientConnectorError: Cannot connect to host api.telegram.org:443 ssl:default [getaddrinfo failed]
15:48:40 | WARNING | aiogram.dispatcher | Sleep for 4.954982 seconds and try again... (tryings = 6, bot id = 7189291350)
15:48:45 | ERROR | aiogram.dispatcher | Failed to fetch updates - TelegramNetworkError: HTTP Client says - ClientConnectorError: Cannot connect to host api.telegram.org:443 ssl:default [getaddrinfo failed]
15:48:45 | WARNING | aiogram.dispatcher | Sleep for 4.985067 seconds and try again... (tryings = 7, bot id = 7189291350)
15:48:50 | ERROR | aiogram.dispatcher | Failed to fetch updates - TelegramNetworkError: HTTP Client says - ClientConnectorError: Cannot connect to host api.telegram.org:443 ssl:default [getaddrinfo failed]
15:48:50 | WARNING | aiogram.dispatcher | Sleep for 4.882073 seconds and try again... (tryings = 8, bot id = 7189291350)
15:48:55 | ERROR | aiogram.dispatcher | Failed to fetch updates - TelegramNetworkError: HTTP Client says - ClientConnectorError: Cannot connect to host api.telegram.org:443 ssl:default [getaddrinfo failed]
15:48:55 | WARNING | aiogram.dispatcher | Sleep for 4.846044 seconds and try again... (tryings = 9, bot id = 7189291350)
15:49:10 | INFO | aiogram.dispatcher | Connection established (tryings = 10, bot id = 7189291350)
15:51:16 | INFO | aiogram.dispatcher | Polling stopped
15:51:16 | INFO | aiogram.dispatcher | Polling stopped for bot @Rich_boostBot id=7189291350 - 'Rich boost'
